Workbook
Name 税金グループ: リスト!$A$2:$A$96

Sheet サービスコードマスタ（入力シート）
B1: 1234
A2: 項目名 | B2: ='サービスコードマスタ（入力シート説明）'!$B7 | C2: ='サービスコードマスタ（入力シート説明）'!$B8 | D2: ='サービスコードマスタ（入力シート説明）'!$B9 | E2: ='サービスコードマスタ（入力シート説明）'!$B10 | F2: ='サービスコードマスタ（入力シート説明）'!$B11 | G2: ='サービスコードマスタ（入力シート説明）'!$B12 | H2: ='サービスコードマスタ（入力シート説明）'!$B13 | I2: ='サービスコードマスタ（入力シート説明）'!$B14 | J2: ='サービスコードマスタ（入力シート説明）'!$B15 | K2: ='サービスコードマスタ（入力シート説明）'!$B16 | L2: ='サービスコードマスタ（入力シート説明）'!$B17 | M2: ='サービスコードマスタ（入力シート説明）'!$B18 | N2: ='サービスコードマスタ（入力シート説明）'!$B19 | O2: ='サービスコードマスタ（入力シート説明）'!$B20 | P2: ='サービスコードマスタ（入力シート説明）'!$B21 | Q2: ='サービスコードマスタ（入力シート説明）'!$B22 | R2: ='サービスコードマスタ（入力シート説明）'!$B23 | S2: ='サービスコードマスタ（入力シート説明）'!$B24 | T2: ='サービスコードマスタ（入力シート説明）'!$B25 | U2: ='サービスコードマスタ（入力シート説明）'!$B26 | V2: ='サービスコードマスタ（入力シート説明）'!$B27 | W2: ='サービスコードマスタ（入力シート説明）'!$B28
A3: データ決定者 | B3: ='サービスコードマスタ（入力シート説明）'!$Q7 | C3: ='サービスコードマスタ（入力シート説明）'!$Q8 | D3: ='サービスコードマスタ（入力シート説明）'!$Q9 | E3: ='サービスコードマスタ（入力シート説明）'!$Q10 | F3: ='サービスコードマスタ（入力シート説明）'!$Q11 | G3: ='サービスコードマスタ（入力シート説明）'!$Q12 | H3: ='サービスコードマスタ（入力シート説明）'!$Q13 | I3: ='サービスコードマスタ（入力シート説明）'!$Q14 | J3: ='サービスコードマスタ（入力シート説明）'!$Q15 | K3: ='サービスコードマスタ（入力シート説明）'!$Q16 | L3: ='サービスコードマスタ（入力シート説明）'!$Q17 | M3: ='サービスコードマスタ（入力シート説明）'!$Q18 | N3: ='サービスコードマスタ（入力シート説明）'!$Q19 | O3: ='サービスコードマスタ（入力シート説明）'!$Q20 | P3: ='サービスコードマスタ（入力シート説明）'!$Q21 | Q3: ='サービスコードマスタ（入力シート説明）'!$Q22 | R3: ='サービスコードマスタ（入力シート説明）'!$Q23 | S3: ='サービスコードマスタ（入力シート説明）'!$Q24 | T3: ='サービスコードマスタ（入力シート説明）'!$Q25 | U3: ='サービスコードマスタ（入力シート説明）'!$Q26 | V3: ='サービスコードマスタ（入力シート説明）'!$Q27 | W3: ='サービスコードマスタ（入力シート説明）'!$Q28
A4: 項目説明 | B4: ='サービスコードマスタ（入力シート説明）'!$K7 | C4: ='サービスコードマスタ（入力シート説明）'!$K8 | D4: ='サービスコードマスタ（入力シート説明）'!$K9 | E4: ='サービスコードマスタ（入力シート説明）'!$K10 | F4: ='サービスコードマスタ（入力シート説明）'!$K11 | G4: ='サービスコードマスタ（入力シート説明）'!$K12 | H4: ='サービスコードマスタ（入力シート説明）'!$K13 | I4: ='サービスコードマスタ（入力シート説明）'!$K14 | J4: ='サービスコードマスタ（入力シート説明）'!$K15 | K4: ='サービスコードマスタ（入力シート説明）'!$K16 | L4: ='サービスコードマスタ（入力シート説明）'!$K17 | M4: ='サービスコードマスタ（入力シート説明）'!$K18 | N4: ='サービスコードマスタ（入力シート説明）'!$K19 | O4: ='サービスコードマスタ（入力シート説明）'!$K20 | P4: ='サービスコードマスタ（入力シート説明）'!$K21 | Q4: ='サービスコードマスタ（入力シート説明）'!$K22 | R4: ='サービスコードマスタ（入力シート説明）'!$K23 | S4: ='サービスコードマスタ（入力シート説明）'!$K24 | T4: ='サービスコードマスタ（入力シート説明）'!$K25 | U4: ='サービスコードマスタ（入力シート説明）'!$K26 | V4: ='サービスコードマスタ（入力シート説明）'!$K27 | W4: ='サービスコードマスタ（入力シート説明）'!$K28
A5: バイト数 | B5: ='サービスコードマスタ（入力シート説明）'!$D7 | C5: ='サービスコードマスタ（入力シート説明）'!$D8 | D5: ='サービスコードマスタ（入力シート説明）'!$D9 | E5: ='サービスコードマスタ（入力シート説明）'!$D10 | F5: ='サービスコードマスタ（入力シート説明）'!$D11 | G5: ='サービスコードマスタ（入力シート説明）'!$D12 | H5: ='サービスコードマスタ（入力シート説明）'!$D13 | I5: ='サービスコードマスタ（入力シート説明）'!$D14 | J5: ='サービスコードマスタ（入力シート説明）'!$D15 | K5: ='サービスコードマスタ（入力シート説明）'!$D16 | L5: ='サービスコードマスタ（入力シート説明）'!$D17 | M5: ='サービスコードマスタ（入力シート説明）'!$D18 | N5: ='サービスコードマスタ（入力シート説明）'!$D19 | O5: ='サービスコードマスタ（入力シート説明）'!$D20 | P5: ='サービスコードマスタ（入力シート説明）'!$D21 | Q5: ='サービスコードマスタ（入力シート説明）'!$D22 | R5: ='サービスコードマスタ（入力シート説明）'!$D23 | S5: ='サービスコードマスタ（入力シート説明）'!$D24 | T5: ='サービスコードマスタ（入力シート説明）'!$D25 | U5: ='サービスコードマスタ（入力シート説明）'!$D26 | V5: ='サービスコードマスタ（入力シート説明）'!$D27 | W5: ='サービスコードマスタ（入力シート説明）'!$D28
A6: 必須区分 | B6: ='サービスコードマスタ（入力シート説明）'!$E7 | C6: ='サービスコードマスタ（入力シート説明）'!$E8 | D6: ='サービスコードマスタ（入力シート説明）'!$E9 | E6: ='サービスコードマスタ（入力シート説明）'!$E10 | F6: ='サービスコードマスタ（入力シート説明）'!$E11 | G6: ='サービスコードマスタ（入力シート説明）'!$E12 | H6: ='サービスコードマスタ（入力シート説明）'!$E13 | I6: ='サービスコードマスタ（入力シート説明）'!$E14 | J6: ='サービスコードマスタ（入力シート説明）'!$E15 | K6: ='サービスコードマスタ（入力シート説明）'!$E16 | L6: ='サービスコードマスタ（入力シート説明）'!$E17 | M6: ='サービスコードマスタ（入力シート説明）'!$E18 | N6: ='サービスコードマスタ（入力シート説明）'!$E19 | O6: ='サービスコードマスタ（入力シート説明）'!$E20 | P6: ='サービスコードマスタ（入力シート説明）'!$E21 | Q6: ='サービスコードマスタ（入力シート説明）'!$E22 | R6: ='サービスコードマスタ（入力シート説明）'!$E23 | S6: ='サービスコードマスタ（入力シート説明）'!$E24 | T6: ='サービスコードマスタ（入力シート説明）'!$E25 | U6: ='サービスコードマスタ（入力シート説明）'!$E26 | V6: ='サービスコードマスタ（入力シート説明）'!$E27 | W6: ='サービスコードマスタ（入力シート説明）'!$E28
A7: - | B7: 1234 | C7: 9000000001 | D7: OK_子値標準（収益） | E7: Y | F7: 20260329 | H7: N | M7: 9000000001 | N7: 0000000000 | O7: Y | R7: Y | S7: 73A | T7: Y | W7: -:データあり
A8: - | B8: 1234 | C8: 1000000001 | D8: NG_チェック2_親かつWBS有 | E8: Y | F8: 20260329 | H8: Y | I8: 2 | J8: C | K8: 1000000001 | L8: 1099999999 | T8: Y | W8: -:データあり
A9: - | B9: 1234 | C9: 2000000001 | D9: NG_チェック3_子かつ費用不一致 | E9: Y | F9: 20260329 | H9: N | M9: 9999999999 | N9: 0000000000 | O9: Y | S9: 73A | T9: Y | W9: -:データあり
A10: - | B10: 1234 | C10: 0000000000 | D10: NG_4-01_費用L不一致（ゼロ埋め） | E10: Y | F10: 20260329 | H10: N | M10: 1111111111 | P10: Y | T10: Y | W10: -:データあり
A11: - | B11: 1234 | C11: 0000000000 | D11: NG_4-02_事業Lあり | E11: Y | F11: 20260329 | H11: N | M11: 0000000000 | N11: 1111111111 | P11: Y | T11: Y | W11: -:データあり
A12: - | B12: 1234 | C12: 0000000000 | D12: NG_4-03_収益Y | E12: Y | F12: 20260329 | H12: N | M12: 0000000000 | O12: Y | P12: Y | T12: Y | W12: 2:追加
A13: - | B13: 1234 | C13: 0000000000 | D13: NG_4-04_費用非Y | E13: Y | F13: 20260329 | H13: N | M13: 0000000000 | P13: N | T13: Y | W13: 2:追加
A14: - | B14: 1234 | C14: 0000000000 | D14: NG_4-05_固定資産Y | E14: Y | F14: 20260329 | H14: N | M14: 0000000000 | P14: Y | Q14: Y | T14: Y | W14: 2:追加
A15: - | B15: 1234 | C15: 0000000000 | D15: NG_4-06_区分経理Y | E15: Y | F15: 20260329 | H15: N | M15: 0000000000 | P15: Y | R15: Y | T15: Y | W15: 2:追加
A16: - | B16: 1234 | C16: 0000000000 | D16: NG_4-07_税金あり | E16: Y | F16: 20260329 | H16: N | M16: 0000000000 | P16: Y | S16: 73A | T16: Y | W16: 2:追加
A17: - | B17: 1234 | C17: 0000000000 | D17: NG_4-08_WBS非Y | E17: Y | F17: 20260329 | H17: N | M17: 0000000000 | P17: Y | T17: N | W17: 2:追加
A18: - | B18: 1001 | C18: 3000000001 | D18: NG_5-01_再編資産区分非Y | E18: Y | F18: 20260329 | H18: N | M18: 3000000001 | N18: 3000000001 | Q18: Y | R18: N | T18: Y | W18: 2:追加
A19: - | B19: 1002 | C19: 3000000002 | D19: NG_5-02_再編資産事業L不一致 | E19: Y | F19: 20260329 | H19: N | M19: 3000000002 | N19: 9999999999 | Q19: Y | R19: Y | T19: Y | W19: 2:追加
A20: - | B20: 8888 | C20: 3000000003 | D20: NG_5-03_非再編資産区分Y | E20: Y | F20: 20260329 | H20: N | M20: 3000000003 | N20: 0000000000 | Q20: Y | R20: Y | T20: Y | W20: 2:追加
A21: - | B21: 8888 | C21: 3000000004 | D21: NG_5-04_非再編資産コード不備 | E21: Y | F21: 20260329 | H21: N | M21: 3000000004 | N21: 0000000000 | Q21: Y | T21: Y | W21: 2:追加
A22: - | B22: 1234 | C22: 4000000001 | D22: NG_6-01_費用のみ税金あり | E22: Y | F22: 20260329 | H22: N | M22: 4000000001 | N22: 0000000000 | P22: Y | S22: 73A | T22: Y | W22: 2:追加
A23: - | B23: 1234 | C23: 4000000002 | D23: NG_6-02_費用のみWBS非Y | E23: Y | F23: 20260329 | H23: N | M23: 4000000002 | N23: 0000000000 | P23: Y | T23: N | W23: 2:追加
A24: - | B24: 1234 | C24: 5000000001 | D24: NG_7-01_収益税金末尾非A | E24: Y | F24: 20260329 | H24: N | M24: 5000000001 | N24: 0000000000 | O24: Y | S24: 73B | T24: Y | W24: 2:追加
A25: - | B25: 1234 | C25: 5000000002 | D25: NG_7-02_収益WBS非Y | E25: Y | F25: 20260329 | H25: N | M25: 5000000002 | N25: 0000000000 | O25: Y | S25: 73A | T25: N | W25: 2:追加
A26: - | B26: 1234 | C26: 5000000003 | D26: NG_7-03_非収益税金あり | E26: Y | F26: 20260329 | H26: N | M26: 5000000003 | N26: 0000000000 | O26: N | S26: 73A | T26: Y | W26: 2:追加
A27: - | B27: 8888 | C27: 6000000001 | D27: NG_8-01_非再編事業L非0 | E27: Y | F27: 20260329 | H27: N | M27: 6000000001 | N27: 1111111111 | O27: Y | S27: 73A | T27: Y | W27: 2:追加
A28: - | B28: 1234 | C28: 7000000001 | D28: NG_9-01_収益費用共NULL | E28: Y | F28: 20260329 | H28: N | M28: 7000000001 | N28: 0000000000 | R28: N | W28: 2:追加
A29: - | B29: 1003 | C29: 9000000002 | D29: OK_9-01例外（再編区分Y） | E29: Y | F29: 20260329 | H29: N | M29: 9000000002 | N29: 9000000002 | R29: Y | W29: 2:追加
A30: - | B30: 1234 | C30: 2100000000 | D30: AAAAAA | E30: Y | F30: 20230126 | H30: Y | I30: 2 | J30: C | K30: 2100000000 | L30: 2199999999 | W30: 1:変更
A31: - | B31: 1234 | C31: 2110000000 | D31: AAAAAA | E31: Y | F31: 20230126 | H31: Y | I31: 3 | J31: C | K31: 2110000000 | L31: 2119999999 | W31: -:データあり
A32: - | B32: 1234 | C32: 2111000000 | D32: AAAAAA | E32: Y | F32: 20230126 | H32: Y | I32: 3 | J32: C | K32: 2111000000 | L32: 2111999999 | W32: -:データあり
A33: - | B33: 1234 | C33: 2112000000 | D33: AAAAAA | E33: N | F33: 20230126 | H33: Y | I33: 3 | J33: C | K33: 2112000000 | L33: 2112999999 | W33: -:データあり
A34: - | B34: 1234 | C34: 2112100100 | D34: AAAAAA | E34: N | F34: 20230126 | H34: Y | I34: 4 | J34: C | K34: 2112100100 | L34: 2112100900 | W34: -:データあり
A35: - | B35: 1234 | C35: 2112100200 | D35: AAAAAA | E35: N | F35: 20230126 | H35: Y | I35: 5 | J35: C | K35: 2112100200 | L35: 2112100900 | W35: 1:変更
A36: - | B36: 1234 | C36: 2112100300 | D36: AAAAAA | E36: N | F36: 20230126 | H36: Y | I36: 6 | J36: C | K36: 2112100300 | L36: 2112100900 | W36: 1:変更
A37: - | B37: 1234 | C37: 2112100400 | D37: AAAAAA | E37: N | F37: 20230126 | H37: Y | I37: 7 | J37: C | K37: 2112100400 | L37: 2112100900 | W37: 1:変更
A38: - | B38: 1234 | C38: 2112100500 | D38: AAAAAA | E38: N | F38: 20230126 | H38: Y | I38: 8 | J38: C | K38: 2112100500 | L38: 2112100900 | W38: 1:変更

Sheet サービスコードマスタ（入力シート説明）
A5: No, | B5: 項目名 | C5: 属性 | D5: バイト数 | E5: 必須（①） | F5: 重複チェック（②） | G5: 項目相関チェック（③） | H5: ①～③の条件詳細 | I5: 禁則文字チェック | J5: 使用目的 | K5: 項目説明 | L5: 設定値 | M5: 入力サンプル | N5: 参照マスタ類 | Q5: データ決定者
B6: インタフェースの項目名を記述 | C6: 登録の形式 | D6: 有効バイト数 | E6: 必須 条件付き必須 任意 | F6: あり なし | G6: あり なし | H6: ①条件付き必須の条件 ②重複チェック内容 ③項目相関チェック内容 上記に該当する内容 | I6: あり なし | J6: 各項目の使用目的（当該マスタ項目を参照する入力系画面、機能処理等）を記述 | K6: 登録する項目の意味・説明を記述 | L6: 取りうる値のリスト、または、範囲 | M6: 入力のサンプル | N6: 関連するシートNo | O6: 関連するシート名 | P6: 該当項目の値が他マスタ類の値を前提としている場合にその条件を記述 | Q6: データの決定者 (CW/BA/各社)
A7: 1 | B7: NTTグループ会社コード | C7: 半角英数 | D7: 4 | E7: 必須 | F7: なし | G7: なし | H7: - | I7: なし | K7: NTTグループ会社を一意に識別するコード | M7: 0002 | O7: 会社マスタ | Q7: 各社
A8: 2 | B8: サービスコード （値） | C8: 半角英数 | D8: 10 | E8: 必須 | F8: あり | G8: なし | H8: ②親値、子値ともに重複不可 | I8: なし | K8: サービスコード | M8: 1111100000 | Q8: 各社
A9: 3 | B9: サービスコード名称 （摘要） | C9: 全半角 | D9: ～240(80) | E9: 必須 | F9: なし | G9: なし | H9: - | I9: あり | K9: サービスコードの名称（80文字） | M9: その他（不動産以外）／物品販売 | Q9: 各社
A10: 4 | B10: 使用可能 | C10: 半角英数 | D10: 1 | E10: 必須 | F10: なし | G10: なし | H10: - | I10: なし | J10: コード値の有効判断に利用 | K10: Y:使用可能、N:使用不可 | L10: Y,N | M10: Y | Q10: 各社
A11: 5 | B11: 有効開始日 | C11: 日付（スラッシュなし） | D11: 8 | E11: 条件付き必須 | F11: なし | G11: なし | H11: ①使用可能がYの場合に必須入力。 | I11: なし | J11: コード値の有効判断に利用 | K11: レコードの有効が開始となる日付を指定。 次期からはMDMに連携する必要があるため、新規追加時や、使用可能をNからYに変更時は入力必須。 ただし、日付設定後は変更不可。 ※形式：YYYYMMDD | M11: 20230401 | Q11: 各社
A12: 6 | B12: 有効終了日 | C12: 日付（スラッシュなし） | D12: 8 | E12: 任意 | F12: なし | G12: あり | H12: ③「有効開始日」<=「有効終了日」であること。 | I12: なし | J12: コード値の有効判断に利用 | K12: レコードの有効が終了となる日付を指定。 ※形式：YYYYMMDD | Q12: 各社
A13: 7 | B13: 親 | C13: 半角英数 | D13: 1 | E13: 必須 | F13: なし | G13: なし | H13: - | I13: なし | J13: 親値／子値の区分 | K13: 親値／子値の区分を指定。 Y:親値（集計値） N:子値（入力値） | L13: Y,N | M13: Y | Q13: 各社
A14: 8 | B14: レベル | C14: 数値 | D14: 1 | E14: 任意 | F14: なし | G14: なし | H14: - | I14: なし | J14: 階層構造の参考情報 | K14: 親値の階層レベルを指定 | L14: 1～9 | M14: 1 | Q14: 各社
A15: 9 | B15: 親値のみ | C15: 半角英数 | D15: 1 | E15: 条件付き必須 | F15: なし | G15: なし | H15: ①「親」が「Y」（親値）のとき必須 ③「親」が「N」（子値）のとき入力不可 | I15: なし | J15: 集計する対象を指定 | K15: 集計する対象を指定。 C:子値 P:親値 ※「親」が「Y」（親値）のとき必須 | L15: C,P | M15: C | Q15: 各社
A16: 10 | B16: 集計範囲（FROM） | C16: 半角英数 | D16: 10 | E16: 条件付き必須 | F16: なし | G16: なし | H16: ①「親」が「Y」（親値）のとき必須 ③「親」が「N」（子値）のとき入力不可 ③集計範囲（FROM）≦集計範囲（TO）であること。 ③集計範囲属性が「P:親値のみ」の場合、 自身の値が集計範囲(FROM)～集計範囲(TO) に含まれないこと。 | I16: なし | J16: 集計する値の開始値を判断 | K16: 子値／親値の集計範囲を指定する場合の開始値を指定。 ※「親」が「Y」（親値）のとき必須 | M16: 1000000000 | Q16: 各社
A17: 11 | B17: 集計範囲（TO） | C17: 半角英数 | D17: 10 | E17: 条件付き必須 | F17: なし | G17: なし | H17: ①「親」が「Y」（親値）のとき必須 ③「親」が「N」（子値）のとき入力不可 ③集計範囲（FROM）≦集計範囲（TO）であること。 ③集計範囲属性が「P:親値のみ」の場合、 自身の値が集計範囲(FROM)～集計範囲(TO) に含まれないこと。 | I17: なし | J17: 集計する値の終了値を判断 | K17: 子値／親値の集計範囲を指定する場合の終了値を指定。 ※「親」が「Y」（親値）のとき必須 | M17: 1999999999 | Q17: 各社
A18: 12 | B18: 費用仕訳レベル | C18: 半角英数 | D18: 10 | E18: 条件付き必須 | F18: なし | G18: あり | H18: ①「親」が「N」（子値）のとき必須 ③「親」が「Y」（親値）のとき入力不可 ③「費用仕訳レベル」が入力されている場合、 「サービスコード（値）」＝「費用仕訳レベル」であること。 | I18: なし | J18: 費用仕訳に設定する粒度のサービスコード | K18: サービス別収支管理を行う場合、費用仕訳のサービスを指定 ※「親」が「N」（子値）のとき必須 | Q18: 各社
A19: 13 | B19: 事業区分レベル | C19: 半角英数 | D19: 10 | E19: 任意 | F19: なし | G19: あり | H19: ③「親」が「Y」（親値）のとき入力不可 ③「会社コード」が持株/東/西/ドコモＢ/LJ/ドコモの場合 「固定資産フラグ」＝Yの場合、 「サービスコード（値）」＝「事業区分レベル」であること。 「固定資産フラグ」が未設定の場合、 「事業区分レベル」が設定されていること。 「事業区分レベル」に設定された「サービスコード」が 他の行に存在し、 「使用可能」＝「Y] かつ 「親」＝「N」 かつ 「固定資産フラグ」＝「Y」であること。 ただし、「サービスコード」＝「0000000000」の場合、 「事業区分レベル」は未設定、または「0000000000」は許容する。 ③「会社コード」が持株/東/西/ドコモＢ/LJ/ドコモ以外の場合、 「サービスコード」＝「0000000000」の場合、 「事業区分レベル」は未設定であること。 「サービスコード」≠「0000000000」、かつ、親＝「N」の場合、 「事業区分レベル」＝「0000000000」であること。 | I19: なし | J19: プロセス/事業区分の組み合わせなどに利用予定 | K19: 事業区分に対応するサービスを設定 | Q19: 各社
A20: 14 | B20: 収益フラグ | C20: 半角英数 | D20: 1 | E20: 任意 | F20: なし | G20: あり | H20: ③「親」が「Y」（親値）のとき入力不可 ③「サービスコード」＝「0000000000」の場合、 「収益フラグ」は未設定であること。 ③「親」＝「N」かつ「区分経理フラグ」＝「Y」以外の場合 「収益フラグ」と「費用フラグ」のどちらかが「Y」であること。 | I20: なし | J20: フラグありの場合収入科目を計上する際に利用可能 | K20: 売上仕訳で利用可能なサービスコードの場合"Y"を設定 | L20: Y | Q20: 各社
A21: 15 | B21: 費用フラグ | C21: 半角英数 | D21: 1 | E21: 任意 | F21: なし | G21: あり | H21: ③「親」が「Y」（親値）のとき入力不可 ③「サービスコード」＝「0000000000」の場合、 「費用フラグ」＝「Y]であること。 ③「親」＝「N」かつ「区分経理フラグ」＝「Y」以外の場合 「収益フラグ」と「費用フラグ」のどちらかが「Y」であること。 | I21: なし | J21: フラグありの場合費用科目を計上する際に利用可能 | K21: 費用仕訳で利用可能なサービスコードの場合"Y"を設定 | L21: Y | Q21: 各社
A22: 16 | B22: 固定資産フラグ | C22: 半角英数 | D22: 1 | E22: 任意 | F22: なし | G22: あり | H22: ③「親」が「Y」（親値）のとき入力不可 ③「サービスコード」＝「0000000000」の場合、 「固定資産フラグ」は未設定であること。 ③「会社コード」が持株、東、西、ドコモＢ、LJ、インフラ、ドコモ以外の場合 「サービスコード」＝「9988999999」の場合、 「固定資産フラグ」＝「Y」であること。 「サービスコード」≠「9988999999」の場合、 「固定資産フラグ」が未設定であること。 | I22: なし | J22: フラグありの場合固定資産に付与する際に利用 | K22: 固定資産で利用可能なサービスコードの場合"Y"を設定 | L22: Y | Q22: 各社
A23: 17 | B23: 区分経理フラグ | C23: 半角英数 | D23: 1 | E23: 任意 | F23: なし | G23: あり | H23: ③「親」が「Y」（親値）のとき入力不可 ③「サービスコード」＝「0000000000」の場合、 「区分経理フラグ」は未設定であること。 ③「会社コード」が東、西、ドコモＢ、LJ、ドコモ以外の場合 「区分経理フラグ」が未設定であること。 ③「会社コード」が東西ドコモＢ＋LJ かつ 「固定資産フラグ」＝「Y」 かつ 「サービスコード」≠9999100002の場合、 「区分経理フラグ」＝「Y」であること。 | I23: なし | J23: フラグありの場合区分経理配賦で使用する際に利用 | K23: 区分経理で利用可能なサービスコードの場合"Y"を設定 | L23: Y | Q23: 各社
A24: 18 | B24: 税金グループ | C24: 半角英数 | D24: 3 | E24: 条件付き必須 | F24: なし | G24: あり | H24: ①「収益フラグ」＝「Y」の場合、入力必須 ③「親」が「Y」（親値）のとき入力不可 ③「サービスコード」＝「0000000000」の場合、 「税金グループ」は未設定であること。 ③「収益フラグ」＝「Y」の場合、 「税金グループ」の3桁目が「A」(売上用の税金G)であること。 「収益フラグ」≠「Y」の場合、 「税金グループ」は未設定であること。 | I24: なし | J24: 税金コードを束ねる税金グループコード | K24: 税金グループマスタに登録されている値を設定 ※「収益フラグ」＝「Y」のとき必須 | L24: 03A,04A,06A,10A,11A,12A,13A,14A,15A,16A,17A,20A,21A,22A,23A,24A,25A,26A,27A,28A,30A,31A,32A,33A,34A,35A,36A,37A,40A,41A,42A,43A,44A,45A,46A,47A,60A,61A,62A,63A,64A,65A,66A,67A,70A,71A,72A,73A,74A,75A,76A,77A,78A,79A,80A,81A,82A,83A,84A,85A,86A,87A,88A,89A,90A,91A,92A,93A,94A,95A,96A,97A,04B,05B,20B,22B,24B,26B,40B,42B,44B,46B,60B,62B,64B,66B,K0B,K2B,K4B,K6B,04C,04D,44D,64D | M24: 04A,77A,64A 等 | O24: 税金グループ／税金コード組合せマスタ | Q24: 各社
A25: 19 | B25: WBSマスタ登録可否フラグ | C25: 半角英数 | D25: 1 | E25: 任意 | F25: なし | G25: あり | H25: ③「親」が「Y」（親値）のとき入力不可 ③「サービスコード」＝「0000000000」の場合、 「WBSマスタ登録可否フラグ」＝「Y」であること。 ③「収益フラグ」＝「Y」 または 「費用フラグ」＝「Y」の場合、 「WBSマスタ登録可否フラグ」＝「Y」であること。 「収益フラグ」が未設定 かつ 「費用フラグ」が未設定の場合、 「WBSマスタ登録可否フラグ」は未設定であること。 | I25: なし | J25: WBSマスタに登録できるか否かの制御フラグ | K25: WBSマスタに登録可能なサービス値は"Y"を設定 | L25: Y | Q25: 各社
A26: 20 | B26: 旧プロダクト | C26: 半角英数 | D26: 6 | E26: 任意 | F26: なし | G26: なし | H26: - | I26: なし | J26: データHUBにおける旧新コード変換に利用 | K26: プロダクトコード | M26: 123456 | Q26: 各社
A27: 21 | B27: 旧事業区分 | C27: 半角英数 | D27: 5 | E27: 任意 | F27: なし | G27: なし | H27: - | I27: なし | J27: データHUBにおける旧新コード変換に利用 | K27: 事業区分コード | M27: 12345 | Q27: 各社
A28: 22 | B28: 更新区分 | C28: 全半角 | D28: 1～ | E28: 条件付き必須 | F28: なし | G28: なし | H28: ①前回報告から変更がある場合は変更内容が設定されていること | I28: なし | J28: 前回報告時（原本）との差分内容を比較する際に利用します。 | K28: 前回報告からの変更内容を設定してください。 1:変更 2:追加 -:データあり | L28: 1:変更,2:追加,-:データあり | M28: 1:変更 | Q28: 各社

Sheet （サービスコードマスタ）入力チェックシート
A1: 会社コードチェック不要 | C1: 最終チェック日時 | D1: 46084.67 | E1: ファイルバージョン：21.08 | F1: 管理番号：9.00 | H1: 00 | I1: 11 | J1: 12 | K1: 13 | L1: 14 | M1: 15 | N1: 16 | O1: 17 | P1: 18 | Q1: 19 | R1: 20 | S1: 21 | T1: 22 | U1: 23 | V1: 24 | W1: 25 | X1: 26 | Y1: 27 | Z1: 28 | AA1: 29 | AB1: 30 | AC1: 31 | AD1: 32 | AE1: 33 | AF1: 34 | AG1: 35 | AH1: 36 | AI1: 37 | AJ1: 38 | AK1: 91 | AL1: 92 | AM1: 93 | AN1: 96 | AO1: 97 | AP1: 99 | AR1: 見直し作業履歴 | AW1: Ж | AX1: 91 | AY1: 91 | AZ1: 93 | BA1: 93 | BB1: 93 | BC1: 96 | BD1: 96 | BE1: 96
A2: No. | B2: 列 | C2: 情報 | D2: 1行：チェックID 2行：チェック内容 3列：項目名 | E2: 入力規則 種別 | F2: 入力規則 設定値 | G2: 固定値 | H2: 必須チェック | I2: 数字チェック | J2: 電話番号チェック | K2: 郵便番号チェック | L2: 日付チェック（スラッシュなし） | M2: 半角英数チェック | N2: 最小バイト長チェック | O2: 最大文字長チェック | P2: 最大バイト長チェック | Q2: 固定長チェック | R2: 全角チェック | S2: 全角カナチェック | T2: 有効値チェック （リスト） | U2: 有効値チェック（範囲） | V2: 禁則文字チェック | W2: 全銀協チェック | X2: 事業所妥当性チェック | Y2: 半角英数大文字・半角スペースチェック | Z2: 半角英数・半角ハイフンチェック | AA2: 全角英数カナチェック | AB2: 半角英数カナチェック | AC2: 全半角英数カナチェック | AD2: 通貨形式チェック | AE2: 半角チェック | AF2: 半角カナチェック | AG2: 半角英数・半角アンダーバーチェック | AH2: 日付チェック（スラッシュあり） | AI2: 全角英数チェック | AJ2: 最大文字数チェック | AK2: 重複チェック | AL2: 条件付 必須／入力不可チェック （申請区分） | AM2: 条件付 必須／入力不可チェック （その他） | AN2: 項目相関チェック | AO2: マスタ相関チェック | AP2: 例外処理 | AQ2: 処理内容 | AR2: 入力シートより | AS2: 事前チェックより | AT2: ＱＡ分析より | AU2: その他 | AV2: 備考 | AW2: 本カラム削除修正厳禁 | AX2: 重複チェック論理式 | AY2: 重複チェック論理式 | AZ2: 条件付必須論理式１ | BA2: 条件付必須論理式２ | BB2: 条件付必須論理式３ | BC2: 項目相関チェック１ | BD2: 項目相関チェック２ | BE2: 項目相関チェック３ | BF2: バイト長拡張係数 | BG2: SJIS表記 | BH2: 【参考】バイト数欄の文字長 | BI2: 【参考】(文字位置 ※最大文字数チェック対象の場合 | BJ2: 【参考】)文字位置 ※最大文字数チェック対象の場合 | BK2: ～文字有無 （0：なし、1：以下、2：以上、 3：範囲） | BL2: 【参考】～文字位置 ※最大／最小バイト長チェック対象の場合
A3: =ROW()-2 | B3: =SUBSTITUTE(ADDRESS(1,ROW()-1,2),"$1","") | D3: =VLOOKUP($A3,'サービスコードマスタ（入力シート説明）'!$A$7:$B$109,2,$A3) | F3: =$T3 | H3: =IF(EXACT(T('サービスコードマスタ（入力シート説明）'!$E7),"必須"),"○","") | I3: =IF(EXACT(T('サービスコードマスタ（入力シート説明）'!$C7),"数値"),"○","") | J3: =IF(EXACT(T('サービスコードマスタ（入力シート説明）'!$C7),"電話番号"),"○","") | K3: =IF(EXACT(T('サービスコードマスタ（入力シート説明）'!$C7),"郵便番号"),"○","") | L3: =IF(EXACT(T('サービスコードマスタ（入力シート説明）'!$C7),"日付（スラッシュなし）"),"○","") | M3: =IF(EXACT(T('サービスコードマスタ（入力シート説明）'!$C7),"半角英数"),"○","") | N3: =IF(ISBLANK('サービスコードマスタ（入力シート説明）'!$D7),"", IF(ISERROR(FIND("～", 'サービスコードマスタ（入力シート説明）'!$D7, 1)), "", IF(EXACT('サービスコードマスタ（入力シート説明）'!$D7,"～"), "", IF(LEN(LEFT('サービスコードマスタ（入力シート説明）'!$D7, FIND("～", 'サービスコードマスタ（入力シート説明）'!$D7, 1) - 1)) >= 1, LEFT('サービスコードマスタ（入力シート説明）'!$D7, FIND("～", 'サービスコードマスタ（入力シート説明）'!$D7, 1) - 1), "")))) | O3: =IF(T3<>"","",IF(OR('サービスコードマスタ（入力シート説明）'!C7="全半角",'サービスコードマスタ（入力シート説明）'!C7="全角",'サービスコードマスタ（入力シート説明）'!C7="全角英数",'サービスコードマスタ（入力シート説明）'!C7="全半角英数カナ",'サービスコードマスタ（入力シート説明）'!C7="全角英数カナ",'サービスコードマスタ（入力シート説明）'!C7="全角カナ",'サービスコードマスタ（入力シート説明）'!C7="半角カナ",'サービスコードマスタ（入力シート説明）'!C7="全銀協"),IF(OR(P3<>"",Q3<>""),TRUNC(IF(P3="",Q3/BF3,P3/BF3),0),""),IF(OR(P3<>"",Q3<>""),IF(P3="",Q3,P3),""))) | P3: =IF(ISBLANK('サービスコードマスタ（入力シート説明）'!$D7),"",IF($BK3=0,"",IF(OR($BK3=1,$BK3=3),MID('サービスコードマスタ（入力シート説明）'!$D7,$BL3+1,IF($BI3="",$BH3,$BI3-1)-$BL3)*IF($BG3<>"",$BF3,1),""))) | Q3: =IF(ISBLANK('サービスコードマスタ（入力シート説明）'!$D7), "", IF($BK3=0, IF($BI3="",'サービスコードマスタ（入力シート説明）'!$D7,LEFT('サービスコードマスタ（入力シート説明）'!$D7,$BI3-1))*IF(BG3<>"",BF3,1),"")) | R3: =IF(EXACT(T('サービスコードマスタ（入力シート説明）'!$C7),"全角"),"○","") | S3: =IF(EXACT(T('サービスコードマスタ（入力シート説明）'!$C7),"全角カナ"),"○","") | T3: =IF(ISBLANK('サービスコードマスタ（入力シート説明）'!$L7),"",IF(ISERROR(FIND("～",'サービスコードマスタ（入力シート説明）'!$L7,1)), 'サービスコードマスタ（入力シート説明）'!$L7, "")) | U3: =IF(ISBLANK('サービスコードマスタ（入力シート説明）'!$L7),"",IF(ISERROR(FIND("～",'サービスコードマスタ（入力シート説明）'!$L7,1)), "", 'サービスコードマスタ（入力シート説明）'!$L7)) | V3: =IF(EXACT(T('サービスコードマスタ（入力シート説明）'!$I7),"あり"),"○","") | W3: =IF(EXACT(T('サービスコードマスタ（入力シート説明）'!$C7),"全銀協"),"○","") | X3: =IF(EXACT(T('サービスコードマスタ（入力シート説明）'!$C7),"事業所コード"),"○","") | Y3: =IF(EXACT(T('サービスコードマスタ（入力シート説明）'!$C7),"半角英数大文字・半角スペース"),"○","") | Z3: =IF(EXACT(T('サービスコードマスタ（入力シート説明）'!$C7),"半角英数・半角ハイフン"),"○","") | AA3: =IF(EXACT(T('サービスコードマスタ（入力シート説明）'!$C7),"全角英数カナ"),"○","") | AB3: =IF(EXACT(T('サービスコードマスタ（入力シート説明）'!$C7),"半角英数カナ"),"○","") | AC3: =IF(EXACT(T('サービスコードマスタ（入力シート説明）'!$C7),"全半角英数カナ"),"○","") | AD3: =IF(EXACT(T('サービスコードマスタ（入力シート説明）'!$C7),"通貨"),"○","") | AE3: =IF(EXACT(T('サービスコードマスタ（入力シート説明）'!$C7),"半角"),"○","") | AF3: =IF(EXACT(T('サービスコードマスタ（入力シート説明）'!$C7),"半角カナ"),"○","") | AG3: =IF(EXACT(T('サービスコードマスタ（入力シート説明）'!$C7),"半角英数・半角アンダーバー"),"○","") | AH3: =IF(EXACT(T('サービスコードマスタ（入力シート説明）'!$C7),"日付（スラッシュあり）"),"○","") | AI3: =IF(EXACT(T('サービスコードマスタ（入力シート説明）'!$C7),"全角英数"),"○","") | AJ3: =IF(ISBLANK('サービスコードマスタ（入力シート説明）'!$D7),"",IF(ISERROR(FIND("(", 'サービスコードマスタ（入力シート説明）'!$D7, 1)),"",MID('サービスコードマスタ（入力シート説明）'!$D7,$BI3+1,$BJ3-$BI3-1))) | AK3: =IF(EXACT(T('サービスコードマスタ（入力シート説明）'!$F7),"あり"),"○","") | AM3: =IF(EXACT(T('サービスコードマスタ（入力シート説明）'!$E7),"条件付き必須"),"○","") | AN3: =IF(EXACT(T('サービスコードマスタ（入力シート説明）'!$G7),"あり"),"○","") | AO3: =IF(ISBLANK('サービスコードマスタ（入力シート説明）'!$N7),"","○") | AQ3: =T('サービスコードマスタ（入力シート説明）'!$H7) | BF3: 1.5 | BH3: =IF(ISBLANK('サービスコードマスタ（入力シート説明）'!$D7),"",LEN('サービスコードマスタ（入力シート説明）'!$D7)) | BI3: =IF(ISBLANK('サービスコードマスタ（入力シート説明）'!$D7),"",IF(ISERROR(FIND("(",'サービスコードマスタ（入力シート説明）'!$D7,1)),"",FIND("(",'サービスコードマスタ（入力シート説明）'!$D7,1))) | BJ3: =IF(ISBLANK('サービスコードマスタ（入力シート説明）'!$D7),"",IF(ISERROR(FIND("(",'サービスコードマスタ（入力シート説明）'!$D7,1)),"",FIND(")",'サービスコードマスタ（入力シート説明）'!$D7,1))) | BK3: =IF(ISBLANK('サービスコードマスタ（入力シート説明）'!$D7),"",IF($BL3="",0,IF($BL3=1,1,IF((IF($BI3="",$BH3,$BI3-1))=$BL3,2,3)))) | BL3: =IF(ISBLANK('サービスコードマスタ（入力シート説明）'!$D7),"",IF(ISERROR(FIND("～",'サービスコードマスタ（入力シート説明）'!$D7,1)),"",FIND("～",'サービスコードマスタ（入力シート説明）'!$D7,1)))
A4: =ROW()-2 | B4: =SUBSTITUTE(ADDRESS(1,ROW()-1,2),"$1","") | D4: =VLOOKUP($A4,'サービスコードマスタ（入力シート説明）'!$A$7:$B$109,2,$A4) | F4: =$T4 | H4: =IF(EXACT(T('サービスコードマスタ（入力シート説明）'!$E8),"必須"),"○","") | I4: =IF(EXACT(T('サービスコードマスタ（入力シート説明）'!$C8),"数値"),"○","") | J4: =IF(EXACT(T('サービスコードマスタ（入力シート説明）'!$C8),"電話番号"),"○","") | K4: =IF(EXACT(T('サービスコードマスタ（入力シート説明）'!$C8),"郵便番号"),"○","") | L4: =IF(EXACT(T('サービスコードマスタ（入力シート説明）'!$C8),"日付（スラッシュなし）"),"○","") | M4: =IF(EXACT(T('サービスコードマスタ（入力シート説明）'!$C8),"半角英数"),"○","") | N4: =IF(ISBLANK('サービスコードマスタ（入力シート説明）'!$D8),"", IF(ISERROR(FIND("～", 'サービスコードマスタ（入力シート説明）'!$D8, 1)), "", IF(EXACT('サービスコードマスタ（入力シート説明）'!$D8,"～"), "", IF(LEN(LEFT('サービスコードマスタ（入力シート説明）'!$D8, FIND("～", 'サービスコードマスタ（入力シート説明）'!$D8, 1) - 1)) >= 1, LEFT('サービスコードマスタ（入力シート説明）'!$D8, FIND("～", 'サービスコードマスタ（入力シート説明）'!$D8, 1) - 1), "")))) | O4: =IF(T4<>"","",IF(OR('サービスコードマスタ（入力シート説明）'!C8="全半角",'サービスコードマスタ（入力シート説明）'!C8="全角",'サービスコードマスタ（入力シート説明）'!C8="全角英数",'サービスコードマスタ（入力シート説明）'!C8="全半角英数カナ",'サービスコードマスタ（入力シート説明）'!C8="全角英数カナ",'サービスコードマスタ（入力シート説明）'!C8="全角カナ",'サービスコードマスタ（入力シート説明）'!C8="半角カナ",'サービスコードマスタ（入力シート説明）'!C8="全銀協"),IF(OR(P4<>"",Q4<>""),TRUNC(IF(P4="",Q4/BF4,P4/BF4),0),""),IF(OR(P4<>"",Q4<>""),IF(P4="",Q4,P4),""))) | P4: =IF(ISBLANK('サービスコードマスタ（入力シート説明）'!$D8),"",IF($BK4=0,"",IF(OR($BK4=1,$BK4=3),MID('サービスコードマスタ（入力シート説明）'!$D8,$BL4+1,IF($BI4="",$BH4,$BI4-1)-$BL4)*IF($BG4<>"",$BF4,1),""))) | Q4: =IF(ISBLANK('サービスコードマスタ（入力シート説明）'!$D8), "", IF($BK4=0, IF($BI4="",'サービスコードマスタ（入力シート説明）'!$D8,LEFT('サービスコードマスタ（入力シート説明）'!$D8,$BI4-1))*IF(BG4<>"",BF4,1),"")) | R4: =IF(EXACT(T('サービスコードマスタ（入力シート説明）'!$C8),"全角"),"○","") | S4: =IF(EXACT(T('サービスコードマスタ（入力シート説明）'!$C8),"全角カナ"),"○","") | T4: =IF(ISBLANK('サービスコードマスタ（入力シート説明）'!$L8),"",IF(ISERROR(FIND("～",'サービスコードマスタ（入力シート説明）'!$L8,1)), 'サービスコードマスタ（入力シート説明）'!$L8, "")) | U4: =IF(ISBLANK('サービスコードマスタ（入力シート説明）'!$L8),"",IF(ISERROR(FIND("～",'サービスコードマスタ（入力シート説明）'!$L8,1)), "", 'サービスコードマスタ（入力シート説明）'!$L8)) | V4: =IF(EXACT(T('サービスコードマスタ（入力シート説明）'!$I8),"あり"),"○","") | W4: =IF(EXACT(T('サービスコードマスタ（入力シート説明）'!$C8),"全銀協"),"○","") | X4: =IF(EXACT(T('サービスコードマスタ（入力シート説明）'!$C8),"事業所コード"),"○","") | Y4: =IF(EXACT(T('サービスコードマスタ（入力シート説明）'!$C8),"半角英数大文字・半角スペース"),"○","") | Z4: =IF(EXACT(T('サービスコードマスタ（入力シート説明）'!$C8),"半角英数・半角ハイフン"),"○","") | AA4: =IF(EXACT(T('サービスコードマスタ（入力シート説明）'!$C8),"全角英数カナ"),"○","") | AB4: =IF(EXACT(T('サービスコードマスタ（入力シート説明）'!$C8),"半角英数カナ"),"○","") | AC4: =IF(EXACT(T('サービスコードマスタ（入力シート説明）'!$C8),"全半角英数カナ"),"○","") | AD4: =IF(EXACT(T('サービスコードマスタ（入力シート説明）'!$C8),"通貨"),"○","") | AE4: =IF(EXACT(T('サービスコードマスタ（入力シート説明）'!$C8),"半角"),"○","") | AF4: =IF(EXACT(T('サービスコードマスタ（入力シート説明）'!$C8),"半角カナ"),"○","") | AG4: =IF(EXACT(T('サービスコードマスタ（入力シート説明）'!$C8),"半角英数・半角アンダーバー"),"○","") | AH4: =IF(EXACT(T('サービスコードマスタ（入力シート説明）'!$C8),"日付（スラッシュあり）"),"○","") | AI4: =IF(EXACT(T('サービスコードマスタ（入力シート説明）'!$C8),"全角英数"),"○","") | AJ4: =IF(ISBLANK('サービスコードマスタ（入力シート説明）'!$D8),"",IF(ISERROR(FIND("(", 'サービスコードマスタ（入力シート説明）'!$D8, 1)),"",MID('サービスコードマスタ（入力シート説明）'!$D8,$BI4+1,$BJ4-$BI4-1))) | AK4: =IF(EXACT(T('サービスコードマスタ（入力シート説明）'!$F8),"あり"),"○","") | AM4: =IF(EXACT(T('サービスコードマスタ（入力シート説明）'!$E8),"条件付き必須"),"○","") | AN4: =IF(EXACT(T('サービスコードマスタ（入力シート説明）'!$G8),"あり"),"○","") | AO4: =IF(ISBLANK('サービスコードマスタ（入力シート説明）'!$N8),"","○") | AQ4: =T('サービスコードマスタ（入力シート説明）'!$H8) | AX4: =("|" & $C7)~C | BF4: 1.5 | BH4: =IF(ISBLANK('サービスコードマスタ（入力シート説明）'!$D8),"",LEN('サービスコードマスタ（入力シート説明）'!$D8)) | BI4: =IF(ISBLANK('サービスコードマスタ（入力シート説明）'!$D8),"",IF(ISERROR(FIND("(",'サービスコードマスタ（入力シート説明）'!$D8,1)),"",FIND("(",'サービスコードマスタ（入力シート説明）'!$D8,1))) | BJ4: =IF(ISBLANK('サービスコードマスタ（入力シート説明）'!$D8),"",IF(ISERROR(FIND("(",'サービスコードマスタ（入力シート説明）'!$D8,1)),"",FIND(")",'サービスコードマスタ（入力シート説明）'!$D8,1))) | BK4: =IF(ISBLANK('サービスコードマスタ（入力シート説明）'!$D8),"",IF($BL4="",0,IF($BL4=1,1,IF((IF($BI4="",$BH4,$BI4-1))=$BL4,2,3)))) | BL4: =IF(ISBLANK('サービスコードマスタ（入力シート説明）'!$D8),"",IF(ISERROR(FIND("～",'サービスコードマスタ（入力シート説明）'!$D8,1)),"",FIND("～",'サービスコードマスタ（入力シート説明）'!$D8,1)))
A5: =ROW()-2 | B5: =SUBSTITUTE(ADDRESS(1,ROW()-1,2),"$1","") | D5: =VLOOKUP($A5,'サービスコードマスタ（入力シート説明）'!$A$7:$B$109,2,$A5) | F5: =$T5 | H5: =IF(EXACT(T('サービスコードマスタ（入力シート説明）'!$E9),"必須"),"○","") | I5: =IF(EXACT(T('サービスコードマスタ（入力シート説明）'!$C9),"数値"),"○","") | J5: =IF(EXACT(T('サービスコードマスタ（入力シート説明）'!$C9),"電話番号"),"○","") | K5: =IF(EXACT(T('サービスコードマスタ（入力シート説明）'!$C9),"郵便番号"),"○","") | L5: =IF(EXACT(T('サービスコードマスタ（入力シート説明）'!$C9),"日付（スラッシュなし）"),"○","") | M5: =IF(EXACT(T('サービスコードマスタ（入力シート説明）'!$C9),"半角英数"),"○","") | N5: =IF(ISBLANK('サービスコードマスタ（入力シート説明）'!$D9),"", IF(ISERROR(FIND("～", 'サービスコードマスタ（入力シート説明）'!$D9, 1)), "", IF(EXACT('サービスコードマスタ（入力シート説明）'!$D9,"～"), "", IF(LEN(LEFT('サービスコードマスタ（入力シート説明）'!$D9, FIND("～", 'サービスコードマスタ（入力シート説明）'!$D9, 1) - 1)) >= 1, LEFT('サービスコードマスタ（入力シート説明）'!$D9, FIND("～", 'サービスコードマスタ（入力シート説明）'!$D9, 1) - 1), "")))) | O5: =IF(T5<>"","",IF(OR('サービスコードマスタ（入力シート説明）'!C9="全半角",'サービスコードマスタ（入力シート説明）'!C9="全角",'サービスコードマスタ（入力シート説明）'!C9="全角英数",'サービスコードマスタ（入力シート説明）'!C9="全半角英数カナ",'サービスコードマスタ（入力シート説明）'!C9="全角英数カナ",'サービスコードマスタ（入力シート説明）'!C9="全角カナ",'サービスコードマスタ（入力シート説明）'!C9="半角カナ",'サービスコードマスタ（入力シート説明）'!C9="全銀協"),IF(OR(P5<>"",Q5<>""),TRUNC(IF(P5="",Q5/BF5,P5/BF5),0),""),IF(OR(P5<>"",Q5<>""),IF(P5="",Q5,P5),""))) | P5: =IF(ISBLANK('サービスコードマスタ（入力シート説明）'!$D9),"",IF($BK5=0,"",IF(OR($BK5=1,$BK5=3),MID('サービスコードマスタ（入力シート説明）'!$D9,$BL5+1,IF($BI5="",$BH5,$BI5-1)-$BL5)*IF($BG5<>"",$BF5,1),""))) | Q5: =IF(ISBLANK('サービスコードマスタ（入力シート説明）'!$D9), "", IF($BK5=0, IF($BI5="",'サービスコードマスタ（入力シート説明）'!$D9,LEFT('サービスコードマスタ（入力シート説明）'!$D9,$BI5-1))*IF(BG5<>"",BF5,1),"")) | R5: =IF(EXACT(T('サービスコードマスタ（入力シート説明）'!$C9),"全角"),"○","") | S5: =IF(EXACT(T('サービスコードマスタ（入力シート説明）'!$C9),"全角カナ"),"○","") | T5: =IF(ISBLANK('サービスコードマスタ（入力シート説明）'!$L9),"",IF(ISERROR(FIND("～",'サービスコードマスタ（入力シート説明）'!$L9,1)), 'サービスコードマスタ（入力シート説明）'!$L9, "")) | U5: =IF(ISBLANK('サービスコードマスタ（入力シート説明）'!$L9),"",IF(ISERROR(FIND("～",'サービスコードマスタ（入力シート説明）'!$L9,1)), "", 'サービスコードマスタ（入力シート説明）'!$L9)) | V5: =IF(EXACT(T('サービスコードマスタ（入力シート説明）'!$I9),"あり"),"○","") | W5: =IF(EXACT(T('サービスコードマスタ（入力シート説明）'!$C9),"全銀協"),"○","") | X5: =IF(EXACT(T('サービスコードマスタ（入力シート説明）'!$C9),"事業所コード"),"○","") | Y5: =IF(EXACT(T('サービスコードマスタ（入力シート説明）'!$C9),"半角英数大文字・半角スペース"),"○","") | Z5: =IF(EXACT(T('サービスコードマスタ（入力シート説明）'!$C9),"半角英数・半角ハイフン"),"○","") | AA5: =IF(EXACT(T('サービスコードマスタ（入力シート説明）'!$C9),"全角英数カナ"),"○","") | AB5: =IF(EXACT(T('サービスコードマスタ（入力シート説明）'!$C9),"半角英数カナ"),"○","") | AC5: =IF(EXACT(T('サービスコードマスタ（入力シート説明）'!$C9),"全半角英数カナ"),"○","") | AD5: =IF(EXACT(T('サービスコードマスタ（入力シート説明）'!$C9),"通貨"),"○","") | AE5: =IF(EXACT(T('サービスコードマスタ（入力シート説明）'!$C9),"半角"),"○","") | AF5: =IF(EXACT(T('サービスコードマスタ（入力シート説明）'!$C9),"半角カナ"),"○","") | AG5: =IF(EXACT(T('サービスコードマスタ（入力シート説明）'!$C9),"半角英数・半角アンダーバー"),"○","") | AH5: =IF(EXACT(T('サービスコードマスタ（入力シート説明）'!$C9),"日付（スラッシュあり）"),"○","") | AI5: =IF(EXACT(T('サービスコードマスタ（入力シート説明）'!$C9),"全角英数"),"○","") | AJ5: =IF(ISBLANK('サービスコードマスタ（入力シート説明）'!$D9),"",IF(ISERROR(FIND("(", 'サービスコードマスタ（入力シート説明）'!$D9, 1)),"",MID('サービスコードマスタ（入力シート説明）'!$D9,$BI5+1,$BJ5-$BI5-1))) | AK5: =IF(EXACT(T('サービスコードマスタ（入力シート説明）'!$F9),"あり"),"○","") | AM5: =IF(EXACT(T('サービスコードマスタ（入力シート説明）'!$E9),"条件付き必須"),"○","") | AN5: =IF(EXACT(T('サービスコードマスタ（入力シート説明）'!$G9),"あり"),"○","") | AO5: =IF(ISBLANK('サービスコードマスタ（入力シート説明）'!$N9),"","○") | AQ5: =T('サービスコードマスタ（入力シート説明）'!$H9) | BF5: 1.5 | BH5: =IF(ISBLANK('サービスコードマスタ（入力シート説明）'!$D9),"",LEN('サービスコードマスタ（入力シート説明）'!$D9)) | BI5: =IF(ISBLANK('サービスコードマスタ（入力シート説明）'!$D9),"",IF(ISERROR(FIND("(",'サービスコードマスタ（入力シート説明）'!$D9,1)),"",FIND("(",'サービスコードマスタ（入力シート説明）'!$D9,1))) | BJ5: =IF(ISBLANK('サービスコードマスタ（入力シート説明）'!$D9),"",IF(ISERROR(FIND("(",'サービスコードマスタ（入力シート説明）'!$D9,1)),"",FIND(")",'サービスコードマスタ（入力シート説明）'!$D9,1))) | BK5: =IF(ISBLANK('サービスコードマスタ（入力シート説明）'!$D9),"",IF($BL5="",0,IF($BL5=1,1,IF((IF($BI5="",$BH5,$BI5-1))=$BL5,2,3)))) | BL5: =IF(ISBLANK('サービスコードマスタ（入力シート説明）'!$D9),"",IF(ISERROR(FIND("～",'サービスコードマスタ（入力シート説明）'!$D9,1)),"",FIND("～",'サービスコードマスタ（入力シート説明）'!$D9,1)))
A6: =ROW()-2 | B6: =SUBSTITUTE(ADDRESS(1,ROW()-1,2),"$1","") | D6: =VLOOKUP($A6,'サービスコードマスタ（入力シート説明）'!$A$7:$B$109,2,$A6) | F6: =$T6 | H6: =IF(EXACT(T('サービスコードマスタ（入力シート説明）'!$E10),"必須"),"○","") | I6: =IF(EXACT(T('サービスコードマスタ（入力シート説明）'!$C10),"数値"),"○","") | J6: =IF(EXACT(T('サービスコードマスタ（入力シート説明）'!$C10),"電話番号"),"○","") | K6: =IF(EXACT(T('サービスコードマスタ（入力シート説明）'!$C10),"郵便番号"),"○","") | L6: =IF(EXACT(T('サービスコードマスタ（入力シート説明）'!$C10),"日付（スラッシュなし）"),"○","") | M6: =IF(EXACT(T('サービスコードマスタ（入力シート説明）'!$C10),"半角英数"),"○","") | N6: =IF(ISBLANK('サービスコードマスタ（入力シート説明）'!$D10),"", IF(ISERROR(FIND("～", 'サービスコードマスタ（入力シート説明）'!$D10, 1)), "", IF(EXACT('サービスコードマスタ（入力シート説明）'!$D10,"～"), "", IF(LEN(LEFT('サービスコードマスタ（入力シート説明）'!$D10, FIND("～", 'サービスコードマスタ（入力シート説明）'!$D10, 1) - 1)) >= 1, LEFT('サービスコードマスタ（入力シート説明）'!$D10, FIND("～", 'サービスコードマスタ（入力シート説明）'!$D10, 1) - 1), "")))) | O6: =IF(T6<>"","",IF(OR('サービスコードマスタ（入力シート説明）'!C10="全半角",'サービスコードマスタ（入力シート説明）'!C10="全角",'サービスコードマスタ（入力シート説明）'!C10="全角英数",'サービスコードマスタ（入力シート説明）'!C10="全半角英数カナ",'サービスコードマスタ（入力シート説明）'!C10="全角英数カナ",'サービスコードマスタ（入力シート説明）'!C10="全角カナ",'サービスコードマスタ（入力シート説明）'!C10="半角カナ",'サービスコードマスタ（入力シート説明）'!C10="全銀協"),IF(OR(P6<>"",Q6<>""),TRUNC(IF(P6="",Q6/BF6,P6/BF6),0),""),IF(OR(P6<>"",Q6<>""),IF(P6="",Q6,P6),""))) | P6: =IF(ISBLANK('サービスコードマスタ（入力シート説明）'!$D10),"",IF($BK6=0,"",IF(OR($BK6=1,$BK6=3),MID('サービスコードマスタ（入力シート説明）'!$D10,$BL6+1,IF($BI6="",$BH6,$BI6-1)-$BL6)*IF($BG6<>"",$BF6,1),""))) | Q6: =IF(ISBLANK('サービスコードマスタ（入力シート説明）'!$D10), "", IF($BK6=0, IF($BI6="",'サービスコードマスタ（入力シート説明）'!$D10,LEFT('サービスコードマスタ（入力シート説明）'!$D10,$BI6-1))*IF(BG6<>"",BF6,1),"")) | R6: =IF(EXACT(T('サービスコードマスタ（入力シート説明）'!$C10),"全角"),"○","") | S6: =IF(EXACT(T('サービスコードマスタ（入力シート説明）'!$C10),"全角カナ"),"○","") | T6: =IF(ISBLANK('サービスコードマスタ（入力シート説明）'!$L10),"",IF(ISERROR(FIND("～",'サービスコードマスタ（入力シート説明）'!$L10,1)), 'サービスコードマスタ（入力シート説明）'!$L10, "")) | U6: =IF(ISBLANK('サービスコードマスタ（入力シート説明）'!$L10),"",IF(ISERROR(FIND("～",'サービスコードマスタ（入力シート説明）'!$L10,1)), "", 'サービスコードマスタ（入力シート説明）'!$L10)) | V6: =IF(EXACT(T('サービスコードマスタ（入力シート説明）'!$I10),"あり"),"○","") | W6: =IF(EXACT(T('サービスコードマスタ（入力シート説明）'!$C10),"全銀協"),"○","") | X6: =IF(EXACT(T('サービスコードマスタ（入力シート説明）'!$C10),"事業所コード"),"○","") | Y6: =IF(EXACT(T('サービスコードマスタ（入力シート説明）'!$C10),"半角英数大文字・半角スペース"),"○","") | Z6: =IF(EXACT(T('サービスコードマスタ（入力シート説明）'!$C10),"半角英数・半角ハイフン"),"○","") | AA6: =IF(EXACT(T('サービスコードマスタ（入力シート説明）'!$C10),"全角英数カナ"),"○","") | AB6: =IF(EXACT(T('サービスコードマスタ（入力シート説明）'!$C10),"半角英数カナ"),"○","") | AC6: =IF(EXACT(T('サービスコードマスタ（入力シート説明）'!$C10),"全半角英数カナ"),"○","") | AD6: =IF(EXACT(T('サービスコードマスタ（入力シート説明）'!$C10),"通貨"),"○","") | AE6: =IF(EXACT(T('サービスコードマスタ（入力シート説明）'!$C10),"半角"),"○","") | AF6: =IF(EXACT(T('サービスコードマスタ（入力シート説明）'!$C10),"半角カナ"),"○","") | AG6: =IF(EXACT(T('サービスコードマスタ（入力シート説明）'!$C10),"半角英数・半角アンダーバー"),"○","") | AH6: =IF(EXACT(T('サービスコードマスタ（入力シート説明）'!$C10),"日付（スラッシュあり）"),"○","") | AI6: =IF(EXACT(T('サービスコードマスタ（入力シート説明）'!$C10),"全角英数"),"○","") | AJ6: =IF(ISBLANK('サービスコードマスタ（入力シート説明）'!$D10),"",IF(ISERROR(FIND("(", 'サービスコードマスタ（入力シート説明）'!$D10, 1)),"",MID('サービスコードマスタ（入力シート説明）'!$D10,$BI6+1,$BJ6-$BI6-1))) | AK6: =IF(EXACT(T('サービスコードマスタ（入力シート説明）'!$F10),"あり"),"○","") | AM6: =IF(EXACT(T('サービスコードマスタ（入力シート説明）'!$E10),"条件付き必須"),"○","") | AN6: =IF(EXACT(T('サービスコードマスタ（入力シート説明）'!$G10),"あり"),"○","") | AO6: =IF(ISBLANK('サービスコードマスタ（入力シート説明）'!$N10),"","○") | AQ6: =T('サービスコードマスタ（入力シート説明）'!$H10) | BF6: 1.5 | BH6: =IF(ISBLANK('サービスコードマスタ（入力シート説明）'!$D10),"",LEN('サービスコードマスタ（入力シート説明）'!$D10)) | BI6: =IF(ISBLANK('サービスコードマスタ（入力シート説明）'!$D10),"",IF(ISERROR(FIND("(",'サービスコードマスタ（入力シート説明）'!$D10,1)),"",FIND("(",'サービスコードマスタ（入力シート説明）'!$D10,1))) | BJ6: =IF(ISBLANK('サービスコードマスタ（入力シート説明）'!$D10),"",IF(ISERROR(FIND("(",'サービスコードマスタ（入力シート説明）'!$D10,1)),"",FIND(")",'サービスコードマスタ（入力シート説明）'!$D10,1))) | BK6: =IF(ISBLANK('サービスコードマスタ（入力シート説明）'!$D10),"",IF($BL6="",0,IF($BL6=1,1,IF((IF($BI6="",$BH6,$BI6-1))=$BL6,2,3)))) | BL6: =IF(ISBLANK('サービスコードマスタ（入力シート説明）'!$D10),"",IF(ISERROR(FIND("～",'サービスコードマスタ（入力シート説明）'!$D10,1)),"",FIND("～",'サービスコードマスタ（入力シート説明）'!$D10,1)))
A7: =ROW()-2 | B7: =SUBSTITUTE(ADDRESS(1,ROW()-1,2),"$1","") | D7: =VLOOKUP($A7,'サービスコードマスタ（入力シート説明）'!$A$7:$B$109,2,$A7) | F7: =$T7 | H7: =IF(EXACT(T('サービスコードマスタ（入力シート説明）'!$E11),"必須"),"○","") | I7: =IF(EXACT(T('サービスコードマスタ（入力シート説明）'!$C11),"数値"),"○","") | J7: =IF(EXACT(T('サービスコードマスタ（入力シート説明）'!$C11),"電話番号"),"○","") | K7: =IF(EXACT(T('サービスコードマスタ（入力シート説明）'!$C11),"郵便番号"),"○","") | L7: =IF(EXACT(T('サービスコードマスタ（入力シート説明）'!$C11),"日付（スラッシュなし）"),"○","") | M7: =IF(EXACT(T('サービスコードマスタ（入力シート説明）'!$C11),"半角英数"),"○","") | N7: =IF(ISBLANK('サービスコードマスタ（入力シート説明）'!$D11),"", IF(ISERROR(FIND("～", 'サービスコードマスタ（入力シート説明）'!$D11, 1)), "", IF(EXACT('サービスコードマスタ（入力シート説明）'!$D11,"～"), "", IF(LEN(LEFT('サービスコードマスタ（入力シート説明）'!$D11, FIND("～", 'サービスコードマスタ（入力シート説明）'!$D11, 1) - 1)) >= 1, LEFT('サービスコードマスタ（入力シート説明）'!$D11, FIND("～", 'サービスコードマスタ（入力シート説明）'!$D11, 1) - 1), "")))) | O7: =IF(T7<>"","",IF(OR('サービスコードマスタ（入力シート説明）'!C11="全半角",'サービスコードマスタ（入力シート説明）'!C11="全角",'サービスコードマスタ（入力シート説明）'!C11="全角英数",'サービスコードマスタ（入力シート説明）'!C11="全半角英数カナ",'サービスコードマスタ（入力シート説明）'!C11="全角英数カナ",'サービスコードマスタ（入力シート説明）'!C11="全角カナ",'サービスコードマスタ（入力シート説明）'!C11="半角カナ",'サービスコードマスタ（入力シート説明）'!C11="全銀協"),IF(OR(P7<>"",Q7<>""),TRUNC(IF(P7="",Q7/BF7,P7/BF7),0),""),IF(OR(P7<>"",Q7<>""),IF(P7="",Q7,P7),""))) | P7: =IF(ISBLANK('サービスコードマスタ（入力シート説明）'!$D11),"",IF($BK7=0,"",IF(OR($BK7=1,$BK7=3),MID('サービスコードマスタ（入力シート説明）'!$D11,$BL7+1,IF($BI7="",$BH7,$BI7-1)-$BL7)*IF($BG7<>"",$BF7,1),""))) | Q7: =IF(ISBLANK('サービスコードマスタ（入力シート説明）'!$D11), "", IF($BK7=0, IF($BI7="",'サービスコードマスタ（入力シート説明）'!$D11,LEFT('サービスコードマスタ（入力シート説明）'!$D11,$BI7-1))*IF(BG7<>"",BF7,1),"")) | R7: =IF(EXACT(T('サービスコードマスタ（入力シート説明）'!$C11),"全角"),"○","") | S7: =IF(EXACT(T('サービスコードマスタ（入力シート説明）'!$C11),"全角カナ"),"○","") | T7: =IF(ISBLANK('サービスコードマスタ（入力シート説明）'!$L11),"",IF(ISERROR(FIND("～",'サービスコードマスタ（入力シート説明）'!$L11,1)), 'サービスコードマスタ（入力シート説明）'!$L11, "")) | U7: =IF(ISBLANK('サービスコードマスタ（入力シート説明）'!$L11),"",IF(ISERROR(FIND("～",'サービスコードマスタ（入力シート説明）'!$L11,1)), "", 'サービスコードマスタ（入力シート説明）'!$L11)) | V7: =IF(EXACT(T('サービスコードマスタ（入力シート説明）'!$I11),"あり"),"○","") | W7: =IF(EXACT(T('サービスコードマスタ（入力シート説明）'!$C11),"全銀協"),"○","") | X7: =IF(EXACT(T('サービスコードマスタ（入力シート説明）'!$C11),"事業所コード"),"○","") | Y7: =IF(EXACT(T('サービスコードマスタ（入力シート説明）'!$C11),"半角英数大文字・半角スペース"),"○","") | Z7: =IF(EXACT(T('サービスコードマスタ（入力シート説明）'!$C11),"半角英数・半角ハイフン"),"○","") | AA7: =IF(EXACT(T('サービスコードマスタ（入力シート説明）'!$C11),"全角英数カナ"),"○","") | AB7: =IF(EXACT(T('サービスコードマスタ（入力シート説明）'!$C11),"半角英数カナ"),"○","") | AC7: =IF(EXACT(T('サービスコードマスタ（入力シート説明）'!$C11),"全半角英数カナ"),"○","") | AD7: =IF(EXACT(T('サービスコードマスタ（入力シート説明）'!$C11),"通貨"),"○","") | AE7: =IF(EXACT(T('サービスコードマスタ（入力シート説明）'!$C11),"半角"),"○","") | AF7: =IF(EXACT(T('サービスコードマスタ（入力シート説明）'!$C11),"半角カナ"),"○","") | AG7: =IF(EXACT(T('サービスコードマスタ（入力シート説明）'!$C11),"半角英数・半角アンダーバー"),"○","") | AH7: =IF(EXACT(T('サービスコードマスタ（入力シート説明）'!$C11),"日付（スラッシュあり）"),"○","") | AI7: =IF(EXACT(T('サービスコードマスタ（入力シート説明）'!$C11),"全角英数"),"○","") | AJ7: =IF(ISBLANK('サービスコードマスタ（入力シート説明）'!$D11),"",IF(ISERROR(FIND("(", 'サービスコードマスタ（入力シート説明）'!$D11, 1)),"",MID('サービスコードマスタ（入力シート説明）'!$D11,$BI7+1,$BJ7-$BI7-1))) | AK7: =IF(EXACT(T('サービスコードマスタ（入力シート説明）'!$F11),"あり"),"○","") | AM7: =IF(EXACT(T('サービスコードマスタ（入力シート説明）'!$E11),"条件付き必須"),"○","") | AN7: =IF(EXACT(T('サービスコードマスタ（入力シート説明）'!$G11),"あり"),"○","") | AO7: =IF(ISBLANK('サービスコードマスタ（入力シート説明）'!$N11),"","○") | AQ7: =T('サービスコードマスタ（入力シート説明）'!$H11) | AZ7: =IF(EXACT($E7,"Y"),LEN($F7)>0,TRUE) | BF7: 1.5 | BH7: =IF(ISBLANK('サービスコードマスタ（入力シート説明）'!$D11),"",LEN('サービスコードマスタ（入力シート説明）'!$D11)) | BI7: =IF(ISBLANK('サービスコードマスタ（入力シート説明）'!$D11),"",IF(ISERROR(FIND("(",'サービスコードマスタ（入力シート説明）'!$D11,1)),"",FIND("(",'サービスコードマスタ（入力シート説明）'!$D11,1))) | BJ7: =IF(ISBLANK('サービスコードマスタ（入力シート説明）'!$D11),"",IF(ISERROR(FIND("(",'サービスコードマスタ（入力シート説明）'!$D11,1)),"",FIND(")",'サービスコードマスタ（入力シート説明）'!$D11,1))) | BK7: =IF(ISBLANK('サービスコードマスタ（入力シート説明）'!$D11),"",IF($BL7="",0,IF($BL7=1,1,IF((IF($BI7="",$BH7,$BI7-1))=$BL7,2,3)))) | BL7: =IF(ISBLANK('サービスコードマスタ（入力シート説明）'!$D11),"",IF(ISERROR(FIND("～",'サービスコードマスタ（入力シート説明）'!$D11,1)),"",FIND("～",'サービスコードマスタ（入力シート説明）'!$D11,1)))
A8: =ROW()-2 | B8: =SUBSTITUTE(ADDRESS(1,ROW()-1,2),"$1","") | D8: =VLOOKUP($A8,'サービスコードマスタ（入力シート説明）'!$A$7:$B$109,2,$A8) | F8: =$T8 | H8: =IF(EXACT(T('サービスコードマスタ（入力シート説明）'!$E12),"必須"),"○","") | I8: =IF(EXACT(T('サービスコードマスタ（入力シート説明）'!$C12),"数値"),"○","") | J8: =IF(EXACT(T('サービスコードマスタ（入力シート説明）'!$C12),"電話番号"),"○","") | K8: =IF(EXACT(T('サービスコードマスタ（入力シート説明）'!$C12),"郵便番号"),"○","") | L8: =IF(EXACT(T('サービスコードマスタ（入力シート説明）'!$C12),"日付（スラッシュなし）"),"○","") | M8: =IF(EXACT(T('サービスコードマスタ（入力シート説明）'!$C12),"半角英数"),"○","") | N8: =IF(ISBLANK('サービスコードマスタ（入力シート説明）'!$D12),"", IF(ISERROR(FIND("～", 'サービスコードマスタ（入力シート説明）'!$D12, 1)), "", IF(EXACT('サービスコードマスタ（入力シート説明）'!$D12,"～"), "", IF(LEN(LEFT('サービスコードマスタ（入力シート説明）'!$D12, FIND("～", 'サービスコードマスタ（入力シート説明）'!$D12, 1) - 1)) >= 1, LEFT('サービスコードマスタ（入力シート説明）'!$D12, FIND("～", 'サービスコードマスタ（入力シート説明）'!$D12, 1) - 1), "")))) | O8: =IF(T8<>"","",IF(OR('サービスコードマスタ（入力シート説明）'!C12="全半角",'サービスコードマスタ（入力シート説明）'!C12="全角",'サービスコードマスタ（入力シート説明）'!C12="全角英数",'サービスコードマスタ（入力シート説明）'!C12="全半角英数カナ",'サービスコードマスタ（入力シート説明）'!C12="全角英数カナ",'サービスコードマスタ（入力シート説明）'!C12="全角カナ",'サービスコードマスタ（入力シート説明）'!C12="半角カナ",'サービスコードマスタ（入力シート説明）'!C12="全銀協"),IF(OR(P8<>"",Q8<>""),TRUNC(IF(P8="",Q8/BF8,P8/BF8),0),""),IF(OR(P8<>"",Q8<>""),IF(P8="",Q8,P8),""))) | P8: =IF(ISBLANK('サービスコードマスタ（入力シート説明）'!$D12),"",IF($BK8=0,"",IF(OR($BK8=1,$BK8=3),MID('サービスコードマスタ（入力シート説明）'!$D12,$BL8+1,IF($BI8="",$BH8,$BI8-1)-$BL8)*IF($BG8<>"",$BF8,1),""))) | Q8: =IF(ISBLANK('サービスコードマスタ（入力シート説明）'!$D12), "", IF($BK8=0, IF($BI8="",'サービスコードマスタ（入力シート説明）'!$D12,LEFT('サービスコードマスタ（入力シート説明）'!$D12,$BI8-1))*IF(BG8<>"",BF8,1),"")) | R8: =IF(EXACT(T('サービスコードマスタ（入力シート説明）'!$C12),"全角"),"○","") | S8: =IF(EXACT(T('サービスコードマスタ（入力シート説明）'!$C12),"全角カナ"),"○","") | T8: =IF(ISBLANK('サービスコードマスタ（入力シート説明）'!$L12),"",IF(ISERROR(FIND("～",'サービスコードマスタ（入力シート説明）'!$L12,1)), 'サービスコードマスタ（入力シート説明）'!$L12, "")) | U8: =IF(ISBLANK('サービスコードマスタ（入力シート説明）'!$L12),"",IF(ISERROR(FIND("～",'サービスコードマスタ（入力シート説明）'!$L12,1)), "", 'サービスコードマスタ（入力シート説明）'!$L12)) | V8: =IF(EXACT(T('サービスコードマスタ（入力シート説明）'!$I12),"あり"),"○","") | W8: =IF(EXACT(T('サービスコードマスタ（入力シート説明）'!$C12),"全銀協"),"○","") | X8: =IF(EXACT(T('サービスコードマスタ（入力シート説明）'!$C12),"事業所コード"),"○","") | Y8: =IF(EXACT(T('サービスコードマスタ（入力シート説明）'!$C12),"半角英数大文字・半角スペース"),"○","") | Z8: =IF(EXACT(T('サービスコードマスタ（入力シート説明）'!$C12),"半角英数・半角ハイフン"),"○","") | AA8: =IF(EXACT(T('サービスコードマスタ（入力シート説明）'!$C12),"全角英数カナ"),"○","") | AB8: =IF(EXACT(T('サービスコードマスタ（入力シート説明）'!$C12),"半角英数カナ"),"○","") | AC8: =IF(EXACT(T('サービスコードマスタ（入力シート説明）'!$C12),"全半角英数カナ"),"○","") | AD8: =IF(EXACT(T('サービスコードマスタ（入力シート説明）'!$C12),"通貨"),"○","") | AE8: =IF(EXACT(T('サービスコードマスタ（入力シート説明）'!$C12),"半角"),"○","") | AF8: =IF(EXACT(T('サービスコードマスタ（入力シート説明）'!$C12),"半角カナ"),"○","") | AG8: =IF(EXACT(T('サービスコードマスタ（入力シート説明）'!$C12),"半角英数・半角アンダーバー"),"○","") | AH8: =IF(EXACT(T('サービスコードマスタ（入力シート説明）'!$C12),"日付（スラッシュあり）"),"○","") | AI8: =IF(EXACT(T('サービスコードマスタ（入力シート説明）'!$C12),"全角英数"),"○","") | AJ8: =IF(ISBLANK('サービスコードマスタ（入力シート説明）'!$D12),"",IF(ISERROR(FIND("(", 'サービスコードマスタ（入力シート説明）'!$D12, 1)),"",MID('サービスコードマスタ（入力シート説明）'!$D12,$BI8+1,$BJ8-$BI8-1))) | AK8: =IF(EXACT(T('サービスコードマスタ（入力シート説明）'!$F12),"あり"),"○","") | AM8: =IF(EXACT(T('サービスコードマスタ（入力シート説明）'!$E12),"条件付き必須"),"○","") | AN8: =IF(EXACT(T('サービスコードマスタ（入力シート説明）'!$G12),"あり"),"○","") | AO8: =IF(ISBLANK('サービスコードマスタ（入力シート説明）'!$N12),"","○") | AQ8: =T('サービスコードマスタ（入力シート説明）'!$H12) | BC8: =IF(ISERR(IF(LEN($F7) <= 0, TRUE, IF(LEN($G7) <= 0, TRUE, $F7 <= $G7))), FALSE, IF(LEN($F7) <= 0, TRUE, IF(LEN($G7) <= 0, TRUE, $F7 <= $G7))) | BF8: 1.5 | BH8: =IF(ISBLANK('サービスコードマスタ（入力シート説明）'!$D12),"",LEN('サービスコードマスタ（入力シート説明）'!$D12)) | BI8: =IF(ISBLANK('サービスコードマスタ（入力シート説明）'!$D12),"",IF(ISERROR(FIND("(",'サービスコードマスタ（入力シート説明）'!$D12,1)),"",FIND("(",'サービスコードマスタ（入力シート説明）'!$D12,1))) | BJ8: =IF(ISBLANK('サービスコードマスタ（入力シート説明）'!$D12),"",IF(ISERROR(FIND("(",'サービスコードマスタ（入力シート説明）'!$D12,1)),"",FIND(")",'サービスコードマスタ（入力シート説明）'!$D12,1))) | BK8: =IF(ISBLANK('サービスコードマスタ（入力シート説明）'!$D12),"",IF($BL8="",0,IF($BL8=1,1,IF((IF($BI8="",$BH8,$BI8-1))=$BL8,2,3)))) | BL8: =IF(ISBLANK('サービスコードマスタ（入力シート説明）'!$D12),"",IF(ISERROR(FIND("～",'サービスコードマスタ（入力シート説明）'!$D12,1)),"",FIND("～",'サービスコードマスタ（入力シート説明）'!$D12,1)))
A9: =ROW()-2 | B9: =SUBSTITUTE(ADDRESS(1,ROW()-1,2),"$1","") | D9: =VLOOKUP($A9,'サービスコードマスタ（入力シート説明）'!$A$7:$B$109,2,$A9) | F9: =$T9 | H9: =IF(EXACT(T('サービスコードマスタ（入力シート説明）'!$E13),"必須"),"○","") | I9: =IF(EXACT(T('サービスコードマスタ（入力シート説明）'!$C13),"数値"),"○","") | J9: =IF(EXACT(T('サービスコードマスタ（入力シート説明）'!$C13),"電話番号"),"○","") | K9: =IF(EXACT(T('サービスコードマスタ（入力シート説明）'!$C13),"郵便番号"),"○","") | L9: =IF(EXACT(T('サービスコードマスタ（入力シート説明）'!$C13),"日付（スラッシュなし）"),"○","") | M9: =IF(EXACT(T('サービスコードマスタ（入力シート説明）'!$C13),"半角英数"),"○","") | N9: =IF(ISBLANK('サービスコードマスタ（入力シート説明）'!$D13),"", IF(ISERROR(FIND("～", 'サービスコードマスタ（入力シート説明）'!$D13, 1)), "", IF(EXACT('サービスコードマスタ（入力シート説明）'!$D13,"～"), "", IF(LEN(LEFT('サービスコードマスタ（入力シート説明）'!$D13, FIND("～", 'サービスコードマスタ（入力シート説明）'!$D13, 1) - 1)) >= 1, LEFT('サービスコードマスタ（入力シート説明）'!$D13, FIND("～", 'サービスコードマスタ（入力シート説明）'!$D13, 1) - 1), "")))) | O9: =IF(T9<>"","",IF(OR('サービスコードマスタ（入力シート説明）'!C13="全半角",'サービスコードマスタ（入力シート説明）'!C13="全角",'サービスコードマスタ（入力シート説明）'!C13="全角英数",'サービスコードマスタ（入力シート説明）'!C13="全半角英数カナ",'サービスコードマスタ（入力シート説明）'!C13="全角英数カナ",'サービスコードマスタ（入力シート説明）'!C13="全角カナ",'サービスコードマスタ（入力シート説明）'!C13="半角カナ",'サービスコードマスタ（入力シート説明）'!C13="全銀協"),IF(OR(P9<>"",Q9<>""),TRUNC(IF(P9="",Q9/BF9,P9/BF9),0),""),IF(OR(P9<>"",Q9<>""),IF(P9="",Q9,P9),""))) | P9: =IF(ISBLANK('サービスコードマスタ（入力シート説明）'!$D13),"",IF($BK9=0,"",IF(OR($BK9=1,$BK9=3),MID('サービスコードマスタ（入力シート説明）'!$D13,$BL9+1,IF($BI9="",$BH9,$BI9-1)-$BL9)*IF($BG9<>"",$BF9,1),""))) | Q9: =IF(ISBLANK('サービスコードマスタ（入力シート説明）'!$D13), "", IF($BK9=0, IF($BI9="",'サービスコードマスタ（入力シート説明）'!$D13,LEFT('サービスコードマスタ（入力シート説明）'!$D13,$BI9-1))*IF(BG9<>"",BF9,1),"")) | R9: =IF(EXACT(T('サービスコードマスタ（入力シート説明）'!$C13),"全角"),"○","") | S9: =IF(EXACT(T('サービスコードマスタ（入力シート説明）'!$C13),"全角カナ"),"○","") | T9: =IF(ISBLANK('サービスコードマスタ（入力シート説明）'!$L13),"",IF(ISERROR(FIND("～",'サービスコードマスタ（入力シート説明）'!$L13,1)), 'サービスコードマスタ（入力シート説明）'!$L13, "")) | U9: =IF(ISBLANK('サービスコードマスタ（入力シート説明）'!$L13),"",IF(ISERROR(FIND("～",'サービスコードマスタ（入力シート説明）'!$L13,1)), "", 'サービスコードマスタ（入力シート説明）'!$L13)) | V9: =IF(EXACT(T('サービスコードマスタ（入力シート説明）'!$I13),"あり"),"○","") | W9: =IF(EXACT(T('サービスコードマスタ（入力シート説明）'!$C13),"全銀協"),"○","") | X9: =IF(EXACT(T('サービスコードマスタ（入力シート説明）'!$C13),"事業所コード"),"○","") | Y9: =IF(EXACT(T('サービスコードマスタ（入力シート説明）'!$C13),"半角英数大文字・半角スペース"),"○","") | Z9: =IF(EXACT(T('サービスコードマスタ（入力シート説明）'!$C13),"半角英数・半角ハイフン"),"○","") | AA9: =IF(EXACT(T('サービスコードマスタ（入力シート説明）'!$C13),"全角英数カナ"),"○","") | AB9: =IF(EXACT(T('サービスコードマスタ（入力シート説明）'!$C13),"半角英数カナ"),"○","") | AC9: =IF(EXACT(T('サービスコードマスタ（入力シート説明）'!$C13),"全半角英数カナ"),"○","") | AD9: =IF(EXACT(T('サービスコードマスタ（入力シート説明）'!$C13),"通貨"),"○","") | AE9: =IF(EXACT(T('サービスコードマスタ（入力シート説明）'!$C13),"半角"),"○","") | AF9: =IF(EXACT(T('サービスコードマスタ（入力シート説明）'!$C13),"半角カナ"),"○","") | AG9: =IF(EXACT(T('サービスコードマスタ（入力シート説明）'!$C13),"半角英数・半角アンダーバー"),"○","") | AH9: =IF(EXACT(T('サービスコードマスタ（入力シート説明）'!$C13),"日付（スラッシュあり）"),"○","") | AI9: =IF(EXACT(T('サービスコードマスタ（入力シート説明）'!$C13),"全角英数"),"○","") | AJ9: =IF(ISBLANK('サービスコードマスタ（入力シート説明）'!$D13),"",IF(ISERROR(FIND("(", 'サービスコードマスタ（入力シート説明）'!$D13, 1)),"",MID('サービスコードマスタ（入力シート説明）'!$D13,$BI9+1,$BJ9-$BI9-1))) | AK9: =IF(EXACT(T('サービスコードマスタ（入力シート説明）'!$F13),"あり"),"○","") | AM9: =IF(EXACT(T('サービスコードマスタ（入力シート説明）'!$E13),"条件付き必須"),"○","") | AN9: =IF(EXACT(T('サービスコードマスタ（入力シート説明）'!$G13),"あり"),"○","") | AO9: =IF(ISBLANK('サービスコードマスタ（入力シート説明）'!$N13),"","○") | AQ9: =T('サービスコードマスタ（入力シート説明）'!$H13) | BF9: 1.5 | BH9: =IF(ISBLANK('サービスコードマスタ（入力シート説明）'!$D13),"",LEN('サービスコードマスタ（入力シート説明）'!$D13)) | BI9: =IF(ISBLANK('サービスコードマスタ（入力シート説明）'!$D13),"",IF(ISERROR(FIND("(",'サービスコードマスタ（入力シート説明）'!$D13,1)),"",FIND("(",'サービスコードマスタ（入力シート説明）'!$D13,1))) | BJ9: =IF(ISBLANK('サービスコードマスタ（入力シート説明）'!$D13),"",IF(ISERROR(FIND("(",'サービスコードマスタ（入力シート説明）'!$D13,1)),"",FIND(")",'サービスコードマスタ（入力シート説明）'!$D13,1))) | BK9: =IF(ISBLANK('サービスコードマスタ（入力シート説明）'!$D13),"",IF($BL9="",0,IF($BL9=1,1,IF((IF($BI9="",$BH9,$BI9-1))=$BL9,2,3)))) | BL9: =IF(ISBLANK('サービスコードマスタ（入力シート説明）'!$D13),"",IF(ISERROR(FIND("～",'サービスコードマスタ（入力シート説明）'!$D13,1)),"",FIND("～",'サービスコードマスタ（入力シート説明）'!$D13,1)))
A10: =ROW()-2 | B10: =SUBSTITUTE(ADDRESS(1,ROW()-1,2),"$1","") | D10: =VLOOKUP($A10,'サービスコードマスタ（入力シート説明）'!$A$7:$B$109,2,$A10) | F10: =$T10 | H10: =IF(EXACT(T('サービスコードマスタ（入力シート説明）'!$E14),"必須"),"○","") | I10: =IF(EXACT(T('サービスコードマスタ（入力シート説明）'!$C14),"数値"),"○","") | J10: =IF(EXACT(T('サービスコードマスタ（入力シート説明）'!$C14),"電話番号"),"○","") | K10: =IF(EXACT(T('サービスコードマスタ（入力シート説明）'!$C14),"郵便番号"),"○","") | L10: =IF(EXACT(T('サービスコードマスタ（入力シート説明）'!$C14),"日付（スラッシュなし）"),"○","") | M10: =IF(EXACT(T('サービスコードマスタ（入力シート説明）'!$C14),"半角英数"),"○","") | N10: =IF(ISBLANK('サービスコードマスタ（入力シート説明）'!$D14),"", IF(ISERROR(FIND("～", 'サービスコードマスタ（入力シート説明）'!$D14, 1)), "", IF(EXACT('サービスコードマスタ（入力シート説明）'!$D14,"～"), "", IF(LEN(LEFT('サービスコードマスタ（入力シート説明）'!$D14, FIND("～", 'サービスコードマスタ（入力シート説明）'!$D14, 1) - 1)) >= 1, LEFT('サービスコードマスタ（入力シート説明）'!$D14, FIND("～", 'サービスコードマスタ（入力シート説明）'!$D14, 1) - 1), "")))) | O10: =IF(T10<>"","",IF(OR('サービスコードマスタ（入力シート説明）'!C14="全半角",'サービスコードマスタ（入力シート説明）'!C14="全角",'サービスコードマスタ（入力シート説明）'!C14="全角英数",'サービスコードマスタ（入力シート説明）'!C14="全半角英数カナ",'サービスコードマスタ（入力シート説明）'!C14="全角英数カナ",'サービスコードマスタ（入力シート説明）'!C14="全角カナ",'サービスコードマスタ（入力シート説明）'!C14="半角カナ",'サービスコードマスタ（入力シート説明）'!C14="全銀協"),IF(OR(P10<>"",Q10<>""),TRUNC(IF(P10="",Q10/BF10,P10/BF10),0),""),IF(OR(P10<>"",Q10<>""),IF(P10="",Q10,P10),""))) | P10: =IF(ISBLANK('サービスコードマスタ（入力シート説明）'!$D14),"",IF($BK10=0,"",IF(OR($BK10=1,$BK10=3),MID('サービスコードマスタ（入力シート説明）'!$D14,$BL10+1,IF($BI10="",$BH10,$BI10-1)-$BL10)*IF($BG10<>"",$BF10,1),""))) | Q10: =IF(ISBLANK('サービスコードマスタ（入力シート説明）'!$D14), "", IF($BK10=0, IF($BI10="",'サービスコードマスタ（入力シート説明）'!$D14,LEFT('サービスコードマスタ（入力シート説明）'!$D14,$BI10-1))*IF(BG10<>"",BF10,1),"")) | R10: =IF(EXACT(T('サービスコードマスタ（入力シート説明）'!$C14),"全角"),"○","") | S10: =IF(EXACT(T('サービスコードマスタ（入力シート説明）'!$C14),"全角カナ"),"○","") | T10: =IF(ISBLANK('サービスコードマスタ（入力シート説明）'!$L14),"",IF(ISERROR(FIND("～",'サービスコードマスタ（入力シート説明）'!$L14,1)), 'サービスコードマスタ（入力シート説明）'!$L14, "")) | U10: =IF(ISBLANK('サービスコードマスタ（入力シート説明）'!$L14),"",IF(ISERROR(FIND("～",'サービスコードマスタ（入力シート説明）'!$L14,1)), "", 'サービスコードマスタ（入力シート説明）'!$L14)) | V10: =IF(EXACT(T('サービスコードマスタ（入力シート説明）'!$I14),"あり"),"○","") | W10: =IF(EXACT(T('サービスコードマスタ（入力シート説明）'!$C14),"全銀協"),"○","") | X10: =IF(EXACT(T('サービスコードマスタ（入力シート説明）'!$C14),"事業所コード"),"○","") | Y10: =IF(EXACT(T('サービスコードマスタ（入力シート説明）'!$C14),"半角英数大文字・半角スペース"),"○","") | Z10: =IF(EXACT(T('サービスコードマスタ（入力シート説明）'!$C14),"半角英数・半角ハイフン"),"○","") | AA10: =IF(EXACT(T('サービスコードマスタ（入力シート説明）'!$C14),"全角英数カナ"),"○","") | AB10: =IF(EXACT(T('サービスコードマスタ（入力シート説明）'!$C14),"半角英数カナ"),"○","") | AC10: =IF(EXACT(T('サービスコードマスタ（入力シート説明）'!$C14),"全半角英数カナ"),"○","") | AD10: =IF(EXACT(T('サービスコードマスタ（入力シート説明）'!$C14),"通貨"),"○","") | AE10: =IF(EXACT(T('サービスコードマスタ（入力シート説明）'!$C14),"半角"),"○","") | AF10: =IF(EXACT(T('サービスコードマスタ（入力シート説明）'!$C14),"半角カナ"),"○","") | AG10: =IF(EXACT(T('サービスコードマスタ（入力シート説明）'!$C14),"半角英数・半角アンダーバー"),"○","") | AH10: =IF(EXACT(T('サービスコードマスタ（入力シート説明）'!$C14),"日付（スラッシュあり）"),"○","") | AI10: =IF(EXACT(T('サービスコードマスタ（入力シート説明）'!$C14),"全角英数"),"○","") | AJ10: =IF(ISBLANK('サービスコードマスタ（入力シート説明）'!$D14),"",IF(ISERROR(FIND("(", 'サービスコードマスタ（入力シート説明）'!$D14, 1)),"",MID('サービスコードマスタ（入力シート説明）'!$D14,$BI10+1,$BJ10-$BI10-1))) | AK10: =IF(EXACT(T('サービスコードマスタ（入力シート説明）'!$F14),"あり"),"○","") | AM10: =IF(EXACT(T('サービスコードマスタ（入力シート説明）'!$E14),"条件付き必須"),"○","") | AN10: =IF(EXACT(T('サービスコードマスタ（入力シート説明）'!$G14),"あり"),"○","") | AO10: =IF(ISBLANK('サービスコードマスタ（入力シート説明）'!$N14),"","○") | AQ10: =T('サービスコードマスタ（入力シート説明）'!$H14) | BF10: 1.5 | BH10: =IF(ISBLANK('サービスコードマスタ（入力シート説明）'!$D14),"",LEN('サービスコードマスタ（入力シート説明）'!$D14)) | BI10: =IF(ISBLANK('サービスコードマスタ（入力シート説明）'!$D14),"",IF(ISERROR(FIND("(",'サービスコードマスタ（入力シート説明）'!$D14,1)),"",FIND("(",'サービスコードマスタ（入力シート説明）'!$D14,1))) | BJ10: =IF(ISBLANK('サービスコードマスタ（入力シート説明）'!$D14),"",IF(ISERROR(FIND("(",'サービスコードマスタ（入力シート説明）'!$D14,1)),"",FIND(")",'サービスコードマスタ（入力シート説明）'!$D14,1))) | BK10: =IF(ISBLANK('サービスコードマスタ（入力シート説明）'!$D14),"",IF($BL10="",0,IF($BL10=1,1,IF((IF($BI10="",$BH10,$BI10-1))=$BL10,2,3)))) | BL10: =IF(ISBLANK('サービスコードマスタ（入力シート説明）'!$D14),"",IF(ISERROR(FIND("～",'サービスコードマスタ（入力シート説明）'!$D14,1)),"",FIND("～",'サービスコードマスタ（入力シート説明）'!$D14,1)))
A11: =ROW()-2 | B11: =SUBSTITUTE(ADDRESS(1,ROW()-1,2),"$1","") | D11: =VLOOKUP($A11,'サービスコードマスタ（入力シート説明）'!$A$7:$B$109,2,$A11) | F11: =$T11 | H11: =IF(EXACT(T('サービスコードマスタ（入力シート説明）'!$E15),"必須"),"○","") | I11: =IF(EXACT(T('サービスコードマスタ（入力シート説明）'!$C15),"数値"),"○","") | J11: =IF(EXACT(T('サービスコードマスタ（入力シート説明）'!$C15),"電話番号"),"○","") | K11: =IF(EXACT(T('サービスコードマスタ（入力シート説明）'!$C15),"郵便番号"),"○","") | L11: =IF(EXACT(T('サービスコードマスタ（入力シート説明）'!$C15),"日付（スラッシュなし）"),"○","") | M11: =IF(EXACT(T('サービスコードマスタ（入力シート説明）'!$C15),"半角英数"),"○","") | N11: =IF(ISBLANK('サービスコードマスタ（入力シート説明）'!$D15),"", IF(ISERROR(FIND("～", 'サービスコードマスタ（入力シート説明）'!$D15, 1)), "", IF(EXACT('サービスコードマスタ（入力シート説明）'!$D15,"～"), "", IF(LEN(LEFT('サービスコードマスタ（入力シート説明）'!$D15, FIND("～", 'サービスコードマスタ（入力シート説明）'!$D15, 1) - 1)) >= 1, LEFT('サービスコードマスタ（入力シート説明）'!$D15, FIND("～", 'サービスコードマスタ（入力シート説明）'!$D15, 1) - 1), "")))) | O11: =IF(T11<>"","",IF(OR('サービスコードマスタ（入力シート説明）'!C15="全半角",'サービスコードマスタ（入力シート説明）'!C15="全角",'サービスコードマスタ（入力シート説明）'!C15="全角英数",'サービスコードマスタ（入力シート説明）'!C15="全半角英数カナ",'サービスコードマスタ（入力シート説明）'!C15="全角英数カナ",'サービスコードマスタ（入力シート説明）'!C15="全角カナ",'サービスコードマスタ（入力シート説明）'!C15="半角カナ",'サービスコードマスタ（入力シート説明）'!C15="全銀協"),IF(OR(P11<>"",Q11<>""),TRUNC(IF(P11="",Q11/BF11,P11/BF11),0),""),IF(OR(P11<>"",Q11<>""),IF(P11="",Q11,P11),""))) | P11: =IF(ISBLANK('サービスコードマスタ（入力シート説明）'!$D15),"",IF($BK11=0,"",IF(OR($BK11=1,$BK11=3),MID('サービスコードマスタ（入力シート説明）'!$D15,$BL11+1,IF($BI11="",$BH11,$BI11-1)-$BL11)*IF($BG11<>"",$BF11,1),""))) | Q11: =IF(ISBLANK('サービスコードマスタ（入力シート説明）'!$D15), "", IF($BK11=0, IF($BI11="",'サービスコードマスタ（入力シート説明）'!$D15,LEFT('サービスコードマスタ（入力シート説明）'!$D15,$BI11-1))*IF(BG11<>"",BF11,1),"")) | R11: =IF(EXACT(T('サービスコードマスタ（入力シート説明）'!$C15),"全角"),"○","") | S11: =IF(EXACT(T('サービスコードマスタ（入力シート説明）'!$C15),"全角カナ"),"○","") | T11: =IF(ISBLANK('サービスコードマスタ（入力シート説明）'!$L15),"",IF(ISERROR(FIND("～",'サービスコードマスタ（入力シート説明）'!$L15,1)), 'サービスコードマスタ（入力シート説明）'!$L15, "")) | U11: =IF(ISBLANK('サービスコードマスタ（入力シート説明）'!$L15),"",IF(ISERROR(FIND("～",'サービスコードマスタ（入力シート説明）'!$L15,1)), "", 'サービスコードマスタ（入力シート説明）'!$L15)) | V11: =IF(EXACT(T('サービスコードマスタ（入力シート説明）'!$I15),"あり"),"○","") | W11: =IF(EXACT(T('サービスコードマスタ（入力シート説明）'!$C15),"全銀協"),"○","") | X11: =IF(EXACT(T('サービスコードマスタ（入力シート説明）'!$C15),"事業所コード"),"○","") | Y11: =IF(EXACT(T('サービスコードマスタ（入力シート説明）'!$C15),"半角英数大文字・半角スペース"),"○","") | Z11: =IF(EXACT(T('サービスコードマスタ（入力シート説明）'!$C15),"半角英数・半角ハイフン"),"○","") | AA11: =IF(EXACT(T('サービスコードマスタ（入力シート説明）'!$C15),"全角英数カナ"),"○","") | AB11: =IF(EXACT(T('サービスコードマスタ（入力シート説明）'!$C15),"半角英数カナ"),"○","") | AC11: =IF(EXACT(T('サービスコードマスタ（入力シート説明）'!$C15),"全半角英数カナ"),"○","") | AD11: =IF(EXACT(T('サービスコードマスタ（入力シート説明）'!$C15),"通貨"),"○","") | AE11: =IF(EXACT(T('サービスコードマスタ（入力シート説明）'!$C15),"半角"),"○","") | AF11: =IF(EXACT(T('サービスコードマスタ（入力シート説明）'!$C15),"半角カナ"),"○","") | AG11: =IF(EXACT(T('サービスコードマスタ（入力シート説明）'!$C15),"半角英数・半角アンダーバー"),"○","") | AH11: =IF(EXACT(T('サービスコードマスタ（入力シート説明）'!$C15),"日付（スラッシュあり）"),"○","") | AI11: =IF(EXACT(T('サービスコードマスタ（入力シート説明）'!$C15),"全角英数"),"○","") | AJ11: =IF(ISBLANK('サービスコードマスタ（入力シート説明）'!$D15),"",IF(ISERROR(FIND("(", 'サービスコードマスタ（入力シート説明）'!$D15, 1)),"",MID('サービスコードマスタ（入力シート説明）'!$D15,$BI11+1,$BJ11-$BI11-1))) | AK11: =IF(EXACT(T('サービスコードマスタ（入力シート説明）'!$F15),"あり"),"○","") | AM11: =IF(EXACT(T('サービスコードマスタ（入力シート説明）'!$E15),"条件付き必須"),"○","") | AN11: =IF(EXACT(T('サービスコードマスタ（入力シート説明）'!$G15),"あり"),"○","") | AO11: =IF(ISBLANK('サービスコードマスタ（入力シート説明）'!$N15),"","○") | AQ11: =T('サービスコードマスタ（入力シート説明）'!$H15) | AZ11: =IF(EXACT($H7,"Y"),LEN($J7)>0,TRUE) | BC11: =IF(EXACT($H7,"N"),LEN($J7)=0,TRUE) | BF11: 1.5 | BH11: =IF(ISBLANK('サービスコードマスタ（入力シート説明）'!$D15),"",LEN('サービスコードマスタ（入力シート説明）'!$D15)) | BI11: =IF(ISBLANK('サービスコードマスタ（入力シート説明）'!$D15),"",IF(ISERROR(FIND("(",'サービスコードマスタ（入力シート説明）'!$D15,1)),"",FIND("(",'サービスコードマスタ（入力シート説明）'!$D15,1))) | BJ11: =IF(ISBLANK('サービスコードマスタ（入力シート説明）'!$D15),"",IF(ISERROR(FIND("(",'サービスコードマスタ（入力シート説明）'!$D15,1)),"",FIND(")",'サービスコードマスタ（入力シート説明）'!$D15,1))) | BK11: =IF(ISBLANK('サービスコードマスタ（入力シート説明）'!$D15),"",IF($BL11="",0,IF($BL11=1,1,IF((IF($BI11="",$BH11,$BI11-1))=$BL11,2,3)))) | BL11: =IF(ISBLANK('サービスコードマスタ（入力シート説明）'!$D15),"",IF(ISERROR(FIND("～",'サービスコードマスタ（入力シート説明）'!$D15,1)),"",FIND("～",'サービスコードマスタ（入力シート説明）'!$D15,1)))
A12: =ROW()-2 | B12: =SUBSTITUTE(ADDRESS(1,ROW()-1,2),"$1","") | D12: =VLOOKUP($A12,'サービスコードマスタ（入力シート説明）'!$A$7:$B$109,2,$A12) | F12: =$T12 | H12: =IF(EXACT(T('サービスコードマスタ（入力シート説明）'!$E16),"必須"),"○","") | I12: =IF(EXACT(T('サービスコードマスタ（入力シート説明）'!$C16),"数値"),"○","") | J12: =IF(EXACT(T('サービスコードマスタ（入力シート説明）'!$C16),"電話番号"),"○","") | K12: =IF(EXACT(T('サービスコードマスタ（入力シート説明）'!$C16),"郵便番号"),"○","") | L12: =IF(EXACT(T('サービスコードマスタ（入力シート説明）'!$C16),"日付（スラッシュなし）"),"○","") | M12: =IF(EXACT(T('サービスコードマスタ（入力シート説明）'!$C16),"半角英数"),"○","") | N12: =IF(ISBLANK('サービスコードマスタ（入力シート説明）'!$D16),"", IF(ISERROR(FIND("～", 'サービスコードマスタ（入力シート説明）'!$D16, 1)), "", IF(EXACT('サービスコードマスタ（入力シート説明）'!$D16,"～"), "", IF(LEN(LEFT('サービスコードマスタ（入力シート説明）'!$D16, FIND("～", 'サービスコードマスタ（入力シート説明）'!$D16, 1) - 1)) >= 1, LEFT('サービスコードマスタ（入力シート説明）'!$D16, FIND("～", 'サービスコードマスタ（入力シート説明）'!$D16, 1) - 1), "")))) | O12: =IF(T12<>"","",IF(OR('サービスコードマスタ（入力シート説明）'!C16="全半角",'サービスコードマスタ（入力シート説明）'!C16="全角",'サービスコードマスタ（入力シート説明）'!C16="全角英数",'サービスコードマスタ（入力シート説明）'!C16="全半角英数カナ",'サービスコードマスタ（入力シート説明）'!C16="全角英数カナ",'サービスコードマスタ（入力シート説明）'!C16="全角カナ",'サービスコードマスタ（入力シート説明）'!C16="半角カナ",'サービスコードマスタ（入力シート説明）'!C16="全銀協"),IF(OR(P12<>"",Q12<>""),TRUNC(IF(P12="",Q12/BF12,P12/BF12),0),""),IF(OR(P12<>"",Q12<>""),IF(P12="",Q12,P12),""))) | P12: =IF(ISBLANK('サービスコードマスタ（入力シート説明）'!$D16),"",IF($BK12=0,"",IF(OR($BK12=1,$BK12=3),MID('サービスコードマスタ（入力シート説明）'!$D16,$BL12+1,IF($BI12="",$BH12,$BI12-1)-$BL12)*IF($BG12<>"",$BF12,1),""))) | Q12: =IF(ISBLANK('サービスコードマスタ（入力シート説明）'!$D16), "", IF($BK12=0, IF($BI12="",'サービスコードマスタ（入力シート説明）'!$D16,LEFT('サービスコードマスタ（入力シート説明）'!$D16,$BI12-1))*IF(BG12<>"",BF12,1),"")) | R12: =IF(EXACT(T('サービスコードマスタ（入力シート説明）'!$C16),"全角"),"○","") | S12: =IF(EXACT(T('サービスコードマスタ（入力シート説明）'!$C16),"全角カナ"),"○","") | T12: =IF(ISBLANK('サービスコードマスタ（入力シート説明）'!$L16),"",IF(ISERROR(FIND("～",'サービスコードマスタ（入力シート説明）'!$L16,1)), 'サービスコードマスタ（入力シート説明）'!$L16, "")) | U12: =IF(ISBLANK('サービスコードマスタ（入力シート説明）'!$L16),"",IF(ISERROR(FIND("～",'サービスコードマスタ（入力シート説明）'!$L16,1)), "", 'サービスコードマスタ（入力シート説明）'!$L16)) | V12: =IF(EXACT(T('サービスコードマスタ（入力シート説明）'!$I16),"あり"),"○","") | W12: =IF(EXACT(T('サービスコードマスタ（入力シート説明）'!$C16),"全銀協"),"○","") | X12: =IF(EXACT(T('サービスコードマスタ（入力シート説明）'!$C16),"事業所コード"),"○","") | Y12: =IF(EXACT(T('サービスコードマスタ（入力シート説明）'!$C16),"半角英数大文字・半角スペース"),"○","") | Z12: =IF(EXACT(T('サービスコードマスタ（入力シート説明）'!$C16),"半角英数・半角ハイフン"),"○","") | AA12: =IF(EXACT(T('サービスコードマスタ（入力シート説明）'!$C16),"全角英数カナ"),"○","") | AB12: =IF(EXACT(T('サービスコードマスタ（入力シート説明）'!$C16),"半角英数カナ"),"○","") | AC12: =IF(EXACT(T('サービスコードマスタ（入力シート説明）'!$C16),"全半角英数カナ"),"○","") | AD12: =IF(EXACT(T('サービスコードマスタ（入力シート説明）'!$C16),"通貨"),"○","") | AE12: =IF(EXACT(T('サービスコードマスタ（入力シート説明）'!$C16),"半角"),"○","") | AF12: =IF(EXACT(T('サービスコードマスタ（入力シート説明）'!$C16),"半角カナ"),"○","") | AG12: =IF(EXACT(T('サービスコードマスタ（入力シート説明）'!$C16),"半角英数・半角アンダーバー"),"○","") | AH12: =IF(EXACT(T('サービスコードマスタ（入力シート説明）'!$C16),"日付（スラッシュあり）"),"○","") | AI12: =IF(EXACT(T('サービスコードマスタ（入力シート説明）'!$C16),"全角英数"),"○","") | AJ12: =IF(ISBLANK('サービスコードマスタ（入力シート説明）'!$D16),"",IF(ISERROR(FIND("(", 'サービスコードマスタ（入力シート説明）'!$D16, 1)),"",MID('サービスコードマスタ（入力シート説明）'!$D16,$BI12+1,$BJ12-$BI12-1))) | AK12: =IF(EXACT(T('サービスコードマスタ（入力シート説明）'!$F16),"あり"),"○","") | AM12: =IF(EXACT(T('サービスコードマスタ（入力シート説明）'!$E16),"条件付き必須"),"○","") | AN12: =IF(EXACT(T('サービスコードマスタ（入力シート説明）'!$G16),"あり"),"○","") | AO12: =IF(ISBLANK('サービスコードマスタ（入力シート説明）'!$N16),"","○") | AP12: ○ | AQ12: =T('サービスコードマスタ（入力シート説明）'!$H16) | AZ12: =IF(EXACT($H7,"Y"),LEN($K7)>0,TRUE) | BC12: =IF(EXACT($H7,"N"),LEN($K7)=0,TRUE) | BF12: 1.5 | BH12: =IF(ISBLANK('サービスコードマスタ（入力シート説明）'!$D16),"",LEN('サービスコードマスタ（入力シート説明）'!$D16)) | BI12: =IF(ISBLANK('サービスコードマスタ（入力シート説明）'!$D16),"",IF(ISERROR(FIND("(",'サービスコードマスタ（入力シート説明）'!$D16,1)),"",FIND("(",'サービスコードマスタ（入力シート説明）'!$D16,1))) | BJ12: =IF(ISBLANK('サービスコードマスタ（入力シート説明）'!$D16),"",IF(ISERROR(FIND("(",'サービスコードマスタ（入力シート説明）'!$D16,1)),"",FIND(")",'サービスコードマスタ（入力シート説明）'!$D16,1))) | BK12: =IF(ISBLANK('サービスコードマスタ（入力シート説明）'!$D16),"",IF($BL12="",0,IF($BL12=1,1,IF((IF($BI12="",$BH12,$BI12-1))=$BL12,2,3)))) | BL12: =IF(ISBLANK('サービスコードマスタ（入力シート説明）'!$D16),"",IF(ISERROR(FIND("～",'サービスコードマスタ（入力シート説明）'!$D16,1)),"",FIND("～",'サービスコードマスタ（入力シート説明）'!$D16,1)))
